Workbook
Name \0: #REF!
Name \A: #REF!
Name \B: #REF!
Name \c: #REF!
Name \D: #REF!
Name \f: #REF!
Name \g: #REF!
Name \k: #REF!
Name \n: #REF!
Name \P: #REF!
Name \Q: #REF!
Name \s: #REF!
Name \X: #REF!
Name \y: #REF!
Name \z: #REF!
Name _.._The_Oaks: #REF!
Name _\A: #REF!
Name _\L: #REF!
Name _\P: #REF!
Name _\s: #REF!
Name _\w: #N/A
Name _\z: #REF!
Name __\a: #REF!
Name __\b: #REF!
Name __\c: #REF!
Name __\m: #REF!
Name __\q: #REF!
Name __\w: #N/A
Name __\z: #REF!
Name _________\a: #REF!
Name _________\b: #REF!
Name _________\c: #REF!
Name _________\m: #REF!
Name __________\z: #REF!
Name ___________\q: #REF!
Name ___________________\q: #REF!
Name __________________________________\a: #REF!
Name __________________________________\b: #REF!
Name _______________________________________\c: #REF!
Name _______________________________________\m: #REF!
Name __________________________a1: #REF!
Name _________________________a1: #REF!
Name ________________________a1: #REF!
Name ________________________RET1: #REF!
Name ________________________RET2: #REF!
Name ________________________RET3: #REF!
Name ________________________RET4: #REF!
Name ________________________RET5: #REF!
Name ________________________RET6: #REF!
Name _______________________a1: #REF!
Name _______________________RET1: #REF!
Name _______________________RET2: #REF!
Name _______________________RET3: #REF!
Name _______________________RET4: #REF!
Name _______________________RET5: #REF!
Name _______________________RET6: #REF!
Name ______________________a1: #REF!
Name ______________________i1: #REF!
Name ______________________RET1: #REF!
Name ______________________RET2: #REF!

Sheet Resumen
F2: Formato Informe Semanal Proyectos Contratistas | L2: Contrato nro W381147
F4: Ecopetrol Desarrollo de Proyectos Vicepresidencias De Desarrollo y Proyectos
F6: EDP-F-052 | G6: Elaborado 02/11/2023 | K6: Versión 4
B10: 1. DATOS GENERALES
B12: Contratista | D12: CONSORCIO IIWA KAI | G12: Fecha de Reporte | H12: De | I12: 46256 | K12: Fechas | L12: Plan | M12: Real / Proyectada
B13: Contrato / Orden de Servicio No. | D13: W381147 – VEE - 002 | H13: Hasta | I13: =+I12+6 -> 46262 | K13: Inicio | L13: 46218 | M13: 46218
G14: Reporte No. | I14: 7 | K14: Finalización | L14: 46617 | M14: 46617
B15: DESCRIPCIÓN OBJETO DEL CONTRATO U ODS | K15: RESUMEN PROGRESO DE CONTRATO U ODS
B16: ONSTRUCCIÓN DE PLATAFORMAS Y CIMENTACIONES DE AEROGENERADORES DEL PARQUE EÓLICO WINDPESHI | K16: PLANEADO | L16: EJECUTADO | M16: DIFERENCIA
K17: =+'C3'!I13 -> 0.0041150005 | L17: =+'C3'!I14 -> 0.000333753 | M17: =+L17-K17 -> -0.0037812475
B19: 2. INDICADORES HSE, PERSONAL Y TIEMPOS
B21: PERSONAL EN CAMPO | D21: DIRECTOS (INCLUYE SUBCONTRATISTAS) | G21: PERSONAL STAFF DEL CONTRATISTA | K21: HH ACUM. CORTE ANTERIOR | L21: HH SEMANA ACTUAL | M21: HH ACUM. SEMANA ACTUAL
D22: REGIÓN | E22: NO REGIÓN | F22: TOTAL | G22: REGIÓN | H22: NO REGIÓN | I22: TOTAL
B23: CALIFICADO | D23: =2+3 -> 5 | E23: 0 | F23: =SUM(D23:E23) -> 5 | G23: 16 | H23: 5 | I23: =SUM(G23:H23) -> 21 | K23: 4249 | L23: 1204 | M23: =+K23+L23 -> 5453
B24: NO CALIFICADO | D24: 3 | E24: 0 | F24: =SUM(D24:E24) -> 3 | G24: 1 | H24: 0 | I24: =SUM(G24:H24) -> 1 | K24: KM ACUM. ANTERIOR | L24: KM SEMANAL ACTUAL | M24: KM. ACUM. ACTUAL
B25: TOTAL | D25: =SUM(D23:D24) -> 8 | E25: =SUM(E23:E24) -> 0 | F25: =SUM(F23:F24) -> 8 | G25: =SUM(G23:G24) -> 17 | H25: =SUM(H23:H24) -> 5 | I25: =SUM(I23:J24) -> 22 | K25: 3440 | L25: 700 | M25: =+IFERROR(SUM(K25:L25),"-") -> 4140
B28: ASPECTOS HSE | F28: ACUMULADO ANTERIORES | G28: SEMANA ACTUAL | H28: ACUMULADO ACTUAL
B29: Indicadores Reactivos | C29: Accidentes con perdida de tiempo | F29: 0 | G29: 0 | H29: =SUM(F29:G29) -> 0
C30: Accidentes sin perdida de tiempo (tratamiento médico y trabajo restringido) | F30: 0 | G30: 0 | H30: =SUM(F30:G30) -> 0 | K30: TRIF | L30: 0
C31: Primeros Auxilios | F31: 0 | G31: 0 | H31: =SUM(F31:G31) -> 0
C32: Derrames | F32: 0 | G32: 0 | H32: =SUM(F32:G32) -> 0
C33: Incidentes viales | F33: 0 | G33: 0 | H33: =SUM(F33:G33) -> 0
B34: Indicadores de Liderazgo | C34: Casi Accidentes | F34: 0 | G34: 0 | H34: =SUM(F34:G34) -> 0
C35: Fallas de control (condiciones inseguras) | F35: 0 | G35: 0 | H35: =SUM(F35:G35) -> 0 | K35: TAV | L35: 0
C36: Aseguramento comportamientos | F36: 0 | G36: 0 | H36: =SUM(F36:G36) -> 0
C37: Visitas Gerenciales | F37: 0 | G37: 0 | H37: =SUM(F37:G37) -> 0
C38: Alcoholimetrías positivas | F38: 0 | G38: 0 | H38: =SUM(F38:G38) -> 0
B43: 3. BALANCE DE COSTOS
B45: BALANCE DE COSTOS DEL CONTRATO | E45: ACUMULADO CORTE ANTERIOR | G45: IVA | I45: TOTAL
B47: Valor del contrato CD | E47: 151047896473 | G47: =(E47*5%)*19% -> 1.434955e+09 | I47: =SUM(E47:H47) -> 1.5248285e+11
B48: AIU 38% | E48: =+E47*0.38 -> 5.7398201e+10 | I48: =SUM(E48:H48) -> 5.7398201e+10
B49: Valor del contrato CD+AIU | E49: =+E47+E48 -> 2.084461e+11 | I49: =SUM(E49:H49) -> 2.084461e+11
B50: Gastos Reembolsables | E50: =+E49*10% -> 2.084461e+10 | I50: =SUM(E50:H50) -> 2.084461e+10
B51: Administracion Gastos Reembolsables | E51: =+E50*1% -> 2.084461e+08 | I51: =SUM(E51:H51) -> 2.084461e+08
B52: Cambios de Alcance Aprobados | E52: 0 | I52: =SUM(E52:H52) -> 0
B53: Total costo directo + AIU + ADM GR | E53: =+E49+E51 -> 2.0865454e+11 | G53: =SUM(G47:H52) -> 1.434955e+09 | I53: =SUM(E53:H53) -> 2.100895e+11
B54: Valor facturado | E54: 0 | G54: 0 | I54: =SUM(E54:H54) -> 0
B56: ESTATUS DE EJECUCIÓN | E56: EJECUTADO ACUMULADO SEMANA ANTERIOR | H56: EJECUTADO SEMANA ACTUAL | K56: EJECUTADO ACUMULADO SEMANA ACTUAL
B57: COSTO DIRECTO | E57: =+'C3'!I19/1.38 -> 50412689 | H57: =+'C3'!J20/1.38 -> 10293807 | K57: =+E57+H57 -> 60706495
B58: COSTO DIRECTO + AIU | E58: =+E57*1.38 -> 69569510 | H58: =+H57*1.38 -> 14205453 | K58: =+E58+H58 -> 83774963
...

Sheet C3
E2: Formato Informe Semanal Proyectos Contratistas | M2: Contrato nro W381147
E4: Ecopetrol Desarrollo de Proyectos Vicepresidencias De Desarrollo y Proyectos
E6: EDP-F-052 | G6: Elaborado 02/11/2023 | K6: Versión 4
A9: En esta pestaña se debe incluir el detalle del C3 del contratitsta para el cálculo del progreso.
C10: S0 | D10: S1 | E10: S2 | F10: S3 | G10: S4 | H10: S5 | I10: S6 | J10: S7 | K10: S8 | L10: S9 | M10: S10 | N10: S11 | O10: S12 | P10: S13 | Q10: S14 | R10: S15 | S10: S16 | T10: S17 | U10: S18 | V10: S19 | W10: S20 | X10: S21 | Y10: S22 | Z10: S23 | AA10: S24 | AB10: S25 | AC10: S26 | AD10: S27 | AE10: S28 | AF10: S29 | AG10: S30 | AH10: S31 | AI10: S32 | AJ10: S33 | AK10: S34 | AL10: S35 | AM10: S36 | AN10: S37 | AO10: S38 | AP10: S39 | AQ10: S40 | AR10: S41 | AS10: S42 | AT10: S43 | AU10: S44 | AV10: S45 | AW10: S46 | AX10: S47 | AY10: S48 | AZ10: S49 | BA10: S50 | BB10: S51 | BC10: S52 | BD10: S53 | BE10: S54 | BF10: S55 | BG10: S56 | BH10: S57 | BI10: S58
C11: S0 | D11: =+C12 -> 46218 | E11: =+D12 -> 46220 | F11: =+E12 -> 46227 | G11: =+F12 -> 46234 | H11: =+G12 -> 46241 | I11: =+H12 -> 46248 | J11: =+I12 -> 46255 | K11: =+J12 -> 46262 | ... BI11: =+BH12 -> 46612
C12: 46218 | D12: =+D11+2 -> 46220 | E12: =+D12+7 -> 46227 | F12: =+E12+7 -> 46234 | G12: =+F12+7 -> 46241 | H12: =+G12+7 -> 46248 | I12: =+H12+7 -> 46255 | J12: =+I12+7 -> 46262 | K12: =+J12+7 -> 46269 | L12: =+K12+7 -> 46276 | ... BI12: =+BH12+7 -> 46619
A13: Plan Acum. Semana | C13: =+'PDT ODS02 EARLY'!I7 -> 0 | D13: =+'PDT ODS02 EARLY'!J7 -> 0 | E13: =+'PDT ODS02 EARLY'!K7 -> 0 | F13: =+'PDT ODS02 EARLY'!L7 -> 0 | G13: =+'PDT ODS02 EARLY'!M7 -> 7.9897664e-05 | H13: =+'PDT ODS02 EARLY'!N7 -> 0.0013001487 | I13: =+'PDT ODS02 EARLY'!O7 -> 0.0041150005 | J13: =+'PDT ODS02 EARLY'!P7 -> 0.0083201005 | ... BI13: =+'PDT ODS02 EARLY'!BO7 -> 1
A14: Real Acum. Semana | C14: =+REAL!I7 -> 1.3902875e-05 | D14: =+REAL!J7 -> 4.1708625e-05 | E14: =+REAL!K7 -> 0.00012512587 | F14: =+REAL!L7 -> 0.00017310339 | G14: =+REAL!M7 -> 0.00023988759 | H14: =+REAL!N7 -> 0.00029899581 | I14: =+REAL!O7 -> 0.000333753 | J14: =+REAL!P7 -> 0.00040190229 | K14: 0.00040190229
A15: Plan Semana | C15: =+C13 -> 0 | D15: =+D13-C13 -> 0 | E15: =+E13-D13 -> 0 | F15: =+F13-E13 -> 0 | G15: =+G13-F13 -> 7.9897664e-05 | H15: =+H13-G13 -> 0.0012202511 | I15: =+I13-H13 -> 0.0028148518 | J15: =+J13-I13 -> 0.0042050999 | K15: =+K13-J13 -> 0.0056878277 | ... BI15: =+BI13-BH13 -> 0
A16: Real Semana | C16: =+REAL!I7 -> 1.3902875e-05 | D16: =+REAL!J7-REAL!I7 -> 2.780575e-05 | E16: =+REAL!K7-REAL!J7 -> 8.3417249e-05 | F16: =+REAL!L9-REAL!K9 -> 0 | G16: =+REAL!M9-REAL!L9 -> 0 | H16: =+REAL!N9-REAL!M9 -> 0 | I16: =+REAL!O9-REAL!N9 -> 0 | J16: =+REAL!P9-REAL!O9 -> 0
A17: Pronóstico Acum. | K17: 0.0004 | L17: =+'PDT ODS02 EARLY'!R7 -> 0.022352659 | M17: =+'PDT ODS02 EARLY'!S7 -> 0.03131998 | N17: =+'PDT ODS02 EARLY'!T7 -> 0.045385517 | O17: =+'PDT ODS02 EARLY'!U7 -> 0.060855714 | P17: =+'PDT ODS02 EARLY'!V7 -> 0.087795191 | Q17: =+'PDT ODS02 EARLY'!W7 -> 0.10764759 | R17: =+'PDT ODS02 EARLY'!X7 -> 0.13055656 | S17: =+'PDT ODS02 EARLY'!Y7 -> 0.16313478 | ... BI17: =+'PDT ODS02 EARLY'!BO7 -> 1
A18: Presupuesto Plan Acum. Semana | C18: =+'PDT ODS02 EARLY'!I5 -> 0 | D18: =+'PDT ODS02 EARLY'!J5 -> 0 | E18: =+'PDT ODS02 EARLY'!K5 -> 0 | F18: =+'PDT ODS02 EARLY'!L5 -> 0 | G18: =+'PDT ODS02 EARLY'!M5 -> 16654356 | H18: =+'PDT ODS02 EARLY'!N5 -> 2.7101093e+08 | I18: =+'PDT ODS02 EARLY'!O5 -> 8.577558e+08 | J18: =+'PDT ODS02 EARLY'!P5 -> 1.7342925e+09 | ... BI18: =+'PDT ODS02 EARLY'!BO5 -> 2.084461e+11
A19: Presupuesto Real Acum. Semana | C19: =+REAL!I5 -> 2898000 | D19: =+REAL!J5 -> 8694000 | E19: =+REAL!K5 -> 26082000 | F19: =+REAL!L5 -> 36082727 | G19: =+REAL!M5 -> 50003633 | H19: =+REAL!N5 -> 62324510 | I19: =+REAL!O5 -> 69569510 | J19: =+REAL!P5 -> 83774963 | K19: 83774963
A20: Presupuesto Real Semana | C20: =+REAL!I5 -> 2898000 | D20: =+REAL!J5-REAL!I5 -> 5796000 | E20: =+REAL!K5-REAL!J5 -> 17388000 | F20: =+REAL!L5-REAL!K5 -> 10000727 | G20: =+REAL!M5-REAL!L5 -> 13920906 | H20: =+REAL!N5-REAL!M5 -> 12320878 | I20: =+REAL!O5-REAL!N5 -> 7245000 | J20: =+REAL!P5-REAL!O5 -> 14205453
A21: Este documento hace parte del procedimiento EDP-P-016 Procedimiento de Control y Seguimiento para Contratistas. Todos los derechos reservados para Ecopetrol S.A. Ninguna reproducción externa copia o transmisión digital de esta publicación puede ser hecha sin permiso escrito. Ningún párrafo de esta publicación puede ser reproducido, copiado o transmitido digitalmente sin un consentimiento escrito o de acuerdo con las leyes que regulan los derechos de autor y con base en la regulación vigente. Este formato se diligencia electrónicamente y no requiere firmas (Se considera validado una vez se envié por correo electrónico por parte del responsable). 2/2

Sheet Alcance Cimentaciones
A1: “CONTRATOS MARCO PARA OBRAS ASOCIADAS A LOS PROYECTOS EÓLICOS EN EL DEPARTAMENTO DE LA GUAJIRA PARA ECOPETROL Y SU GRUPO EMPRESARIAL” Alcance 2: Cimentaciones de gran volumen
H2: 1.510479e+11
H3: 5.7398201e+10
H4: 2.084461e+11
A5: ESPECIALIDAD | B5: ITEM | C5: DESCRIPCIÓN DE PARTIDA ASOCIADA | D5: DESCRIPCIÓN | E5: UND PAGO | F5: CANTIDAD CIMENTACIONES | G5: VR UNIT | H5: Vr TOTAL CIMENTACIONES | I5: 1
A6: CIV | B6: 1. OBRAS CIVILES
A7: CIV | B7: 1.1. PRELIMINARES
A8: CIV | B8: 1.1.1 | C8: 6.1. DMP DESBROCE Y LIMPIEZA | D8: DESBROCE Y LIMPIEZA | E8: m2 | F8: 163167 | G8: 4140 | H8: 675511380
A9: CIV | B9: 1.1.2 | C9: 6.2 DMP ROCERÍA, INCLUYE TALA DE ARBOLES CON DAP ≤ A 0.15 m, INCLUYE TRANSPORTE Y DISPOSICIÓN FINAL | D9: ROCERÍA, INCLUYE TALA DE ARBOLES CON DAP ≤ A 0.15 m, INCLUYE TRANSPORTE Y DISPOSICIÓN FINAL | E9: m2 | F9: 0 | G9: 12785 | H9: 0
A10: CIV | B10: 1.1.3 | C10: 6.3 DMP TALA DE ÁRBOLES CON DAP>0.15M, INCLUYE TRANSPORTE Y DISPOSICIÓN FINAL | D10: DMP TALA DE ÁRBOLES CON DAP>0.15M, INCLUYE TRANSPORTE Y DISPOSICIÓN FINAL | E10: Und | F10: 0 | G10: 680000 | H10: 0
A11: CIV | B11: 1.1.4 | C11: 6.4. DMP DESMONTE, DESCAPOTE Y LIMPIEZA | D11: DESMONTE, DESCAPOTE Y LIMPIEZA INCLUYE TALA DE ARBOLES CON DAP ≤0.15M, TRANSPORTE Y DISPOSICIÓN FINAL | E11: m2 | F11: 163167 | G11: 7121 | H11: 1161912207
A12: CIV | B12: 1.1.5 | C12: 6.5. DMP CAMPAMENTOS (ZONA DE FAENAS) | D12: CAMPAMENTOS ( ZONA DE FAENAS) | E12: MES
A13: CIV | B13: 1.1.5.1 | C13: 6.5.1. DMP ALQUILER DE CONTENEDOR 40 FT SALA REUINIONES / OFICINA | D13: ALQUILER DE CONTENEDOR 40 FT SALA REUINIONES / OFICINA | E13: MES | F13: 405 | G13: 4252868 | H13: 1722411540
A14: CIV | B14: 1.1.5.2 | C14: 6.5.2. DMP ALQUILER DE CONTENEDOR 40 FT CAFETERIA | D14: ALQUILER DE CONTENEDOR 40 FT CAFETERIA | E14: MES | F14: 75 | G14: 4252868 | H14: 318965100
A15: CIV | B15: 1.1.5.3 | C15: 6.5.3. DMP ALQUILER DE CONTENEDOR 40 FT ATENCIÓN EMERGENCIA | D15: ALQUILER DE CONTENEDOR 40 FT ATENCIÓN EMERGENCIA | E15: MES | F15: 15 | G15: 4473440 | H15: 67101600
A16: CIV | B16: 1.1.5.4 | C16: 6.5.4. DMP ALQUILER DE CONTENEDOR 40 FT BODEGA | D16: ALQUILER DE CONTENEDOR 40 FT BODEGA | E16: MES | F16: 15 | G16: 3811724 | H16: 57175860
A17: CIV | B17: 1.1.5.5 | C17: 6.5.5 DMP ALQUILER DE CONTENEDOR 40 FT CASILLEROS Y VESTIERES | D17: ALQUILER DE CONTENEDOR 40 FT CASILLEROS Y VESTIERES | E17: MES | F17: 30 | G17: 3811724 | H17: 114351720
A18: CIV | B18: 1.1.5.6 | C18: 6.5.6. DMP ALQUILER GENERADOR ELECTRICO 150 KVA | D18: ALQUILER GENERADOR ELECTRICO 150 KVA | E18: MES | F18: 15 | G18: 48667800 | H18: 730017000
A19: CIV | B19: 1.1.5.7 | C19: 6.5.7. DMP ALQUILER BATERÍA DE BAÑOS CON SERVICIO DE ASEO | D19: ALQUILER BATERÍA DE BAÑOS CON SERVICIO DE ASEO | E19: MES | F19: 30 | G19: 2704032 | H19: 81120960
A20: CIV | B20: 1.1.5.8 | C20: 6.5.8. DMP SERVICIO DE AMBULANCIA TIPO TAM | D20: SERVICIO DE AMBULANCIA TIPO TAM | E20: MES | F20: 15 | G20: 75157500 | H20: 1127362500
A21: CIV | B21: 1.1.5.9 | C21: 6.5.9. DMP ALQUILER TANQUE ALMACENAMIENTO AGUA 50 M3 | D21: ALQUILER TANQUE ALMACENAMIENTO AGUA 50 M3 | E21: MES | F21: 30 | G21: 6743000 | H21: 202290000
A22: CIV | B22: 1.1.5.10 | C22: 6.5.10. DMP SUMINISTRO DE AGUA PARA CAMPAMENTO | D22: SUMINISTRO DE AGUA PARA CAMPAMENTO | E22: m3 | F22: 2700 | G22: 360618 | H22: 973668600
A23: CIV | B23: 1.1.5.11 | C23: 6.5.11. DMP SERVICIO DE VIGILACIA DEL CAMPAMENTO 24 HORAS EN EL AREA DE FAENAS | D23: SERVICIO DE VIGILACIA DEL CAMPAMENTO 24 HORAS EN EL AREA DE FAENAS | E23: MES | F23: 15 | G23: 33500000 | H23: 502500000
A24: CIV | B24: 1.1.5.12 | C24: 6.5.12. DMP SERVICIO DE ASEO EN EL AREA DE CAMPAMENTOS (FAENAS) | D24: SERVICIO DE ASEO EN EL AREA DE CAMPAMENTOS (FAENAS) | E24: MES | F24: 15 | G24: 10489481 | H24: 157342215
A25: CIV | B25: 1.2. MOVIMIENTO DE TIERRA
A26: CIV | B26: 1.2.1 | C26: 6.6. DMP EXCAVACIÓN MANUAL EN MATERIAL COMÚN | D26: EXCAVACIÓN MANUAL EN MATERIAL COMÚN | E26: m3 | F26: 0 | G26: 397150 | H26: 0
A27: CIV | B27: 1.2.2 | C27: 6.7. DMP EXCAVACIÓN MECÁNICA EN MATERIAL COMÚN | D27: EXCAVACIÓN MECÁNICA EN MATERIAL COMÚN | E27: m3 | F27: 163167 | G27: 35495 | H27: 5791612665
A28: CIV | B28: 1.2.3 | C28: 6.8. DMP EXCAVACIÓN MANUAL EN MATERIAL COMÚN CON NIVEL FREÁTICO. INCLUYE TRANSPORTE A UNA DISTANCIA ≤ A 1KM | D28: EXCAVACIÓN MANUAL EN MATERIAL COMÚN CON NIVEL FREÁTICO. INCLUYE TRANSPORTE A UNA DISTANCIA ≤ A 1KM | E28: m3 | G28: 420000 | H28: 0
A29: CIV | B29: 1.2.4 | C29: 6.9. DMP EXCAVACIÓN PARA REPARACIÓN DE PAVIMENTO ASFALTICO EXISTENTE, INCLUYE EL CORTE Y LA REMOCIÓN DE LAS CAPAS ASFÁLTICA SUBYACENTES | D29: EXCAVACIÓN PARA REPARACIÓN DE PAVIMENTO ASFALTICO EXISTENTE, INCLUYE EL CORTE Y LA REMOCIÓN DE LAS CAPAS ASFÁLTICA SUBYACENTES | E29: m3 | F29: 0 | G29: 825364 | H29: 0
A30: CIV | B30: 1.2.5 | C30: 6.10. DMP EXCAVACIÓN EN ROCA | D30: EXCAVACIÓN EN ROCA | E30: m3 | F30: 14088 | G30: 135191 | H30: 1904570808
A31: CIV | B31: 1.2.6 | C31: 6.11. DMP EXCAVACIÓN Y RELLENO COMPENSADO | D31: EXCAVACIÓN Y RELLENO COMPENSADO | E31: m3 | F31: 0 | G31: 67508 | H31: 0
A32: CIV | B32: 1.2.7 | C32: 6.12. DMP DEMOLICIÓN MANUAL Y MECÁNICA | D32: DEMOLICIÓN MANUAL Y TRITURACIÓN DE ELEMENTOS Y ESTRUCTURAS DE CONCRETO | E32: m3 | F32: 0 | G32: 1010418 | H32: 0
A33: CIV | B33: 1.2.7A | C33: 6.12. DMP DEMOLICIÓN MANUAL Y MECÁNICA | D33: DEMOLICIÓN MECÁNICA Y TRITURACIÓN DE ELEMENTOS Y ESTRUCTURAS DE CONCRETO | E33: m3 | F33: 0 | G33: 671437 | H33: 0
A34: CIV | B34: 1.2.8 | C34: 6.13. DMP DEMOLICIÓN MANUAL DE CONCRETO | D34: DEMOLICIÓN MANUAL DE CONCRETO | E34: m3 | F34: 0 | G34: 1013292 | H34: 0
A35: CIV | B35: 1.2.9 | C35: 6.14. DMP DEMOLICIÓN MECÁNICA DE CONCRETO | D35: DEMOLICIÓN MECÁNICA DE CONCRETO | E35: m3 | F35: 0 | G35: 559531 | H35: 0
A36: CIV | B36: 1.2.10 | C36: 6.14. DMP DEMOLICIÓN DE PAVIMENTO FLEXIBLE | D36: DEMOLICIÓN DE PAVIMENTO FLEXIBLE | E36: m3 | F36: 0 | G36: 510299 | H36: 0
A37: CIV | B37: 1.2.11 | C37: 6.16. DMP DEMOLICIÓN MUROS EN MAMPOSTERÍA | D37: DEMOLICIÓN MUROS EN MAMPOSTERÍA | E37: m2 | F37: 0 | G37: 70953 | H37: 0
A38: CIV | B38: 1.2.12 | C38: 6.17. DMP DESMANTELAMIENTO CERRAMIENTO EN ALAMBRE DE PÚAS | D38: DESMANTELAMIENTO CERRAMIENTO EN ALAMBRE DE PÚAS | E38: ml | F38: 0 | G38: 17208 | H38: 0
A39: CIV | B39: 1.2.13 | C39: 6.18. DMP ACARREO DE MATERIAL. DISTANCIA > 2.0 km, INCLUYE CARGUE | D39: ACARREO DE MATERIAL. DISTANCIA > 2.0 km, INCLUYE CARGUE | E39: m3-Km | F39: 0 | G39: 2800 | H39: 0
A40: CIV | B40: 1.2.14 | C40: 6.19. DMP COMPACTACIÓN MANUAL | D40: COMPACTACIÓN MANUAL | E40: m3 | F40: 0 | G40: 198575 | H40: 0
...

Sheet Curva "S" Avance Físico
A1: =+'PDT ODS02 EARLY'!B3 -> CW381147-ODS002: CONSTRUCCIÓN DE PLATAFORMAS Y CIMENTACIONES DE AEROGENERADORES DEL PARQUE EÓLICO WINDPESHI

Sheet PDT ODS02 EARLY
B3: CW381147-ODS002: CONSTRUCCIÓN DE PLATAFORMAS Y CIMENTACIONES DE AEROGENERADORES DEL PARQUE EÓLICO WINDPESHI | H3: SEMANAS | I3: 0 | J3: 1 | K3: 2 | L3: 3 | M3: 4 | N3: 5 | O3: 6 | P3: 7 | Q3: 8 | R3: 9 | S3: 10 | T3: 11 | U3: 12 | V3: 13 | W3: 14 | X3: 15 | Y3: 16 | Z3: 17 | AA3: 18 | AB3: 19 | AC3: 20 | AD3: 21 | AE3: 22 | AF3: 23 | AG3: 24 | AH3: 25 | AI3: 26 | AJ3: 27 | AK3: 28 | AL3: 29 | AM3: 30 | AN3: 31 | AO3: 32 | AP3: 33 | AQ3: 34 | AR3: 35 | AS3: 36 | AT3: 37 | AU3: 38 | AV3: 39 | AW3: 40 | AX3: 41 | AY3: 42 | AZ3: 43 | BA3: 44 | BB3: 45 | BC3: 46 | BD3: 47 | BE3: 48 | BF3: 49 | BG3: 50 | BH3: 51 | BI3: 52 | BJ3: 53 | BK3: 54 | BL3: 55 | BM3: 56 | BN3: 57 | BO3: 58
I4: =G8 -> 46218 | J4: =I4+2 -> 46220 | K4: =J4+7 -> 46227 | L4: =K4+7 -> 46234 | M4: =L4+7 -> 46241 | N4: =M4+7 -> 46248 | O4: =N4+7 -> 46255 | P4: =O4+7 -> 46262 | Q4: =P4+7 -> 46269 | R4: =Q4+7 -> 46276 | ... BO4: =BN4+7 -> 46619
H5: AVANCES PROGRAMADOS | I5: =I7*$E$8 -> 0 | J5: =J7*$E$8 -> 0 | K5: =K7*$E$8 -> 0 | L5: =L7*$E$8 -> 0 | M5: =M7*$E$8 -> 16654356 | N5: =N7*$E$8 -> 2.7101093e+08 | O5: =O7*$E$8 -> 8.577558e+08 | P5: =P7*$E$8 -> 1.7342925e+09 | ... BO5: =BO7*$E$8 -> 2.084461e+11
H6: FECHAS | I6: =I4 -> 46218 | J6: =J4 -> 46220 | K6: =K4 -> 46227 | L6: =L4 -> 46234 | M6: =M4 -> 46241 | N6: =N4 -> 46248 | O6: =O4 -> 46255 | P6: =P4 -> 46262 | ... BO6: =BO4 -> 46619
B7: EDT | C7: Nombre de tarea | D7: Duración | E7: Costo | F7: PESO RELATIVO AL CAPITULO (%) | G7: Comienzo | H7: Fin | I7: =$F34*I34+$F39*I39+$F44*I44+$F109*I109+$F689*I689+$F695*I695+$F699*I699 -> 0 | J7: =$F34*J34+$F39*J39+$F44*J44+$F109*J109+$F689*J689+$F695*J695+$F699*J699 -> 0 | K7: =$F34*K34+$F39*K39+$F44*K44+$F109*K109+$F689*K689+$F695*K695+$F699*K699 -> 0 | L7: =$F34*L34+$F39*L39+$F44*L44+$F109*L109+$F689*L689+$F695*L695+$F699*L699 -> 0 | M7: =$F34*M34+$F39*M39+$F44*M44+$F109*M109+$F689*M689+$F695*M695+$F699*M699 -> 7.9897664e-05 | N7: =$F34*N34+$F39*N39+$F44*N44+$F109*N109+$F689*N689+$F695*N695+$F699*N699 -> 0.0013001487 | O7: =$F34*O34+$F39*O39+$F44*O44+$F109*O109+$F689*O689+$F695*O695+$F699*O699 -> 0.0041150005 | P7: =$F34*P34+$F39*P39+$F44*P44+$F109*P109+$F689*P689+$F695*P695+$F699*P699 -> 0.0083201005 | ... BO7: =$F34*BO34+$F39*BO39+$F44*BO44+$F109*BO109+$F689*BO689+$F695*BO695+$F699*BO699 -> 1
B8: 0 | C8: ODS02_IIWAKAI | D8: 357 días | E8: =+E34+E39+E44+E109+E689+E695+E699 -> 2.084461e+11 | F8: =+F10+F14++F29+F30+F34+F39+F44+F109+F689+F695+F699 -> 1 | G8: 46218 | H8: 46617 | I8: =I7*$E$8 -> 0 | J8: =J7*$E$8 -> 0 | K8: =K7*$E$8 -> 0 | L8: =L7*$E$8 -> 0 | M8: =M7*$E$8 -> 16654356 | N8: =N7*$E$8 -> 2.7101093e+08 | O8: =O7*$E$8 -> 8.577558e+08 | P8: =P7*$E$8 -> 1.7342925e+09 | ... BO8: =BO7*$E$8 -> 2.084461e+11
B9: 1 | C9: HITO 1: ACTA DE INICIO | D9: 0 días | E9: =VLOOKUP(B9,'Cuadro Control'!C5:J1939,8,FALSE) -> 0 | F9: =IFERROR(E9/$E$8,0) -> 0 | G9: 46218 | H9: 46218 | I9: =IF($G9=0,0,IF(I$6<$G9,0,IF(I$6>$H9,1,(I$6-$G9+1)/($H9-$G9+1)))) -> 1 | J9: =IF($G9=0,0,IF(J$6<$G9,0,IF(J$6>$H9,1,(J$6-$G9+1)/($H9-$G9+1)))) -> 1 | K9: =IF($G9=0,0,IF(K$6<$G9,0,IF(K$6>$H9,1,(K$6-$G9+1)/($H9-$G9+1)))) -> 1 | L9: =IF($G9=0,0,IF(L$6<$G9,0,IF(L$6>$H9,1,(L$6-$G9+1)/($H9-$G9+1)))) -> 1 | M9: =IF($G9=0,0,IF(M$6<$G9,0,IF(M$6>$H9,1,(M$6-$G9+1)/($H9-$G9+1)))) -> 1 | N9: =IF($G9=0,0,IF(N$6<$G9,0,IF(N$6>$H9,1,(N$6-$G9+1)/($H9-$G9+1)))) -> 1 | O9: =IF($G9=0,0,IF(O$6<$G9,0,IF(O$6>$H9,1,(O$6-$G9+1)/($H9-$G9+1)))) -> 1 | P9: =IF($G9=0,0,IF(P$6<$G9,0,IF(P$6>$H9,1,(P$6-$G9+1)/($H9-$G9+1)))) -> 1 | ... BO9: =IF($G9=0,0,IF(BO$6<$G9,0,IF(BO$6>$H9,1,(BO$6-$G9+1)/($H9-$G9+1)))) -> 1
B10: 2 | C10: PRELIMINARES GENERALES | D10: 21 días | E10: =VLOOKUP(B10,'Cuadro Control'!C6:J1940,8,FALSE) -> 0 | F10: =IFERROR(E10/$E$8,0) -> 0 | G10: 46218 | H10: 46240 | I10: =IF($G10=0,0,IF(I$6<$G10,0,IF(I$6>$H10,1,(I$6-$G10+1)/($H10-$G10+1)))) -> 0.043478261 | J10: =IF($G10=0,0,IF(J$6<$G10,0,IF(J$6>$H10,1,(J$6-$G10+1)/($H10-$G10+1)))) -> 0.13043478 | K10: =IF($G10=0,0,IF(K$6<$G10,0,IF(K$6>$H10,1,(K$6-$G10+1)/($H10-$G10+1)))) -> 0.43478261 | L10: =IF($G10=0,0,IF(L$6<$G10,0,IF(L$6>$H10,1,(L$6-$G10+1)/($H10-$G10+1)))) -> 0.73913043 | M10: =IF($G10=0,0,IF(M$6<$G10,0,IF(M$6>$H10,1,(M$6-$G10+1)/($H10-$G10+1)))) -> 1 | N10: =IF($G10=0,0,IF(N$6<$G10,0,IF(N$6>$H10,1,(N$6-$G10+1)/($H10-$G10+1)))) -> 1 | O10: =IF($G10=0,0,IF(O$6<$G10,0,IF(O$6>$H10,1,(O$6-$G10+1)/($H10-$G10+1)))) -> 1 | P10: =IF($G10=0,0,IF(P$6<$G10,0,IF(P$6>$H10,1,(P$6-$G10+1)/($H10-$G10+1)))) -> 1 | ... BO10: =IF($G10=0,0,IF(BO$6<$G10,0,IF(BO$6>$H10,1,(BO$6-$G10+1)/($H10-$G10+1)))) -> 1
B11: 2.1 | C11: ENTREGA DE DOCUMENTOS HABILITADORES | D11: 0 días | E11: =VLOOKUP(B11,'Cuadro Control'!C7:J1941,8,FALSE) -> 0 | F11: =IFERROR(E11/$E$8,0) -> 0 | G11: 46218 | H11: 46218 | I11: =IF($G11=0,0,IF(I$6<$G11,0,IF(I$6>$H11,1,(I$6-$G11+1)/($H11-$G11+1)))) -> 1 | J11: =IF($G11=0,0,IF(J$6<$G11,0,IF(J$6>$H11,1,(J$6-$G11+1)/($H11-$G11+1)))) -> 1 | K11: =IF($G11=0,0,IF(K$6<$G11,0,IF(K$6>$H11,1,(K$6-$G11+1)/($H11-$G11+1)))) -> 1 | L11: =IF($G11=0,0,IF(L$6<$G11,0,IF(L$6>$H11,1,(L$6-$G11+1)/($H11-$G11+1)))) -> 1 | M11: =IF($G11=0,0,IF(M$6<$G11,0,IF(M$6>$H11,1,(M$6-$G11+1)/($H11-$G11+1)))) -> 1 | N11: =IF($G11=0,0,IF(N$6<$G11,0,IF(N$6>$H11,1,(N$6-$G11+1)/($H11-$G11+1)))) -> 1 | O11: =IF($G11=0,0,IF(O$6<$G11,0,IF(O$6>$H11,1,(O$6-$G11+1)/($H11-$G11+1)))) -> 1 | P11: =IF($G11=0,0,IF(P$6<$G11,0,IF(P$6>$H11,1,(P$6-$G11+1)/($H11-$G11+1)))) -> 1 | ... BO11: =IF($G11=0,0,IF(BO$6<$G11,0,IF(BO$6>$H11,1,(BO$6-$G11+1)/($H11-$G11+1)))) -> 1
B12: 2.2 | C12: ENTREGA DE DOCUMENTACIÓN DE EJECUCION DEL PROYECTO | D12: 0 días | E12: =VLOOKUP(B12,'Cuadro Control'!C8:J1942,8,FALSE) -> 0 | F12: =IFERROR(E12/$E$8,0) -> 0 | G12: 46218 | H12: 46218 | I12: =IF($G12=0,0,IF(I$6<$G12,0,IF(I$6>$H12,1,(I$6-$G12+1)/($H12-$G12+1)))) -> 1 | J12: =IF($G12=0,0,IF(J$6<$G12,0,IF(J$6>$H12,1,(J$6-$G12+1)/($H12-$G12+1)))) -> 1 | K12: =IF($G12=0,0,IF(K$6<$G12,0,IF(K$6>$H12,1,(K$6-$G12+1)/($H12-$G12+1)))) -> 1 | L12: =IF($G12=0,0,IF(L$6<$G12,0,IF(L$6>$H12,1,(L$6-$G12+1)/($H12-$G12+1)))) -> 1 | M12: =IF($G12=0,0,IF(M$6<$G12,0,IF(M$6>$H12,1,(M$6-$G12+1)/($H12-$G12+1)))) -> 1 | N12: =IF($G12=0,0,IF(N$6<$G12,0,IF(N$6>$H12,1,(N$6-$G12+1)/($H12-$G12+1)))) -> 1 | O12: =IF($G12=0,0,IF(O$6<$G12,0,IF(O$6>$H12,1,(O$6-$G12+1)/($H12-$G12+1)))) -> 1 | P12: =IF($G12=0,0,IF(P$6<$G12,0,IF(P$6>$H12,1,(P$6-$G12+1)/($H12-$G12+1)))) -> 1 | ... BO12: =IF($G12=0,0,IF(BO$6<$G12,0,IF(BO$6>$H12,1,(BO$6-$G12+1)/($H12-$G12+1)))) -> 1
B13: 2.3 | C13: REVISIÓN Y RECEPCIÓN DE INGENIERIA | D13: 21 días | E13: =VLOOKUP(B13,'Cuadro Control'!C9:J1943,8,FALSE) -> 0 | F13: =IFERROR(E13/$E$8,0) -> 0 | G13: 46218 | H13: 46240 | I13: =IF($G13=0,0,IF(I$6<$G13,0,IF(I$6>$H13,1,(I$6-$G13+1)/($H13-$G13+1)))) -> 0.043478261 | J13: =IF($G13=0,0,IF(J$6<$G13,0,IF(J$6>$H13,1,(J$6-$G13+1)/($H13-$G13+1)))) -> 0.13043478 | K13: =IF($G13=0,0,IF(K$6<$G13,0,IF(K$6>$H13,1,(K$6-$G13+1)/($H13-$G13+1)))) -> 0.43478261 | L13: =IF($G13=0,0,IF(L$6<$G13,0,IF(L$6>$H13,1,(L$6-$G13+1)/($H13-$G13+1)))) -> 0.73913043 | M13: =IF($G13=0,0,IF(M$6<$G13,0,IF(M$6>$H13,1,(M$6-$G13+1)/($H13-$G13+1)))) -> 1 | N13: =IF($G13=0,0,IF(N$6<$G13,0,IF(N$6>$H13,1,(N$6-$G13+1)/($H13-$G13+1)))) -> 1 | O13: =IF($G13=0,0,IF(O$6<$G13,0,IF(O$6>$H13,1,(O$6-$G13+1)/($H13-$G13+1)))) -> 1 | P13: =IF($G13=0,0,IF(P$6<$G13,0,IF(P$6>$H13,1,(P$6-$G13+1)/($H13-$G13+1)))) -> 1 | ... BO13: =IF($G13=0,0,IF(BO$6<$G13,0,IF(BO$6>$H13,1,(BO$6-$G13+1)/($H13-$G13+1)))) -> 1
B14: 3 | C14: SOCIALIZACIÓN CON COMUNIDADES | D14: 30 días | E14: =VLOOKUP(B14,'Cuadro Control'!C10:J1944,8,FALSE) -> 0 | F14: =IFERROR(E14/$E$8,0) -> 0 | G14: 46218 | H14: 46252 | I14: =IF($G14=0,0,IF(I$6<$G14,0,IF(I$6>$H14,1,(I$6-$G14+1)/($H14-$G14+1)))) -> 0.028571429 | J14: =IF($G14=0,0,IF(J$6<$G14,0,IF(J$6>$H14,1,(J$6-$G14+1)/($H14-$G14+1)))) -> 0.085714286 | K14: =IF($G14=0,0,IF(K$6<$G14,0,IF(K$6>$H14,1,(K$6-$G14+1)/($H14-$G14+1)))) -> 0.28571429 | L14: =IF($G14=0,0,IF(L$6<$G14,0,IF(L$6>$H14,1,(L$6-$G14+1)/($H14-$G14+1)))) -> 0.48571429 | M14: =IF($G14=0,0,IF(M$6<$G14,0,IF(M$6>$H14,1,(M$6-$G14+1)/($H14-$G14+1)))) -> 0.68571429 | N14: =IF($G14=0,0,IF(N$6<$G14,0,IF(N$6>$H14,1,(N$6-$G14+1)/($H14-$G14+1)))) -> 0.88571429 | O14: =IF($G14=0,0,IF(O$6<$G14,0,IF(O$6>$H14,1,(O$6-$G14+1)/($H14-$G14+1)))) -> 1 | P14: =IF($G14=0,0,IF(P$6<$G14,0,IF(P$6>$H14,1,(P$6-$G14+1)/($H14-$G14+1)))) -> 1 | ... BO14: =IF($G14=0,0,IF(BO$6<$G14,0,IF(BO$6>$H14,1,(BO$6-$G14+1)/($H14-$G14+1)))) -> 1
B15: 3.1 | C15: REUNIONES RIO PATAJATAMA | D15: 0 días | E15: =VLOOKUP(B15,'Cuadro Control'!C11:J1945,8,FALSE) -> 0 | F15: =IFERROR(E15/$E$8,0) -> 0 | G15: 46218 | H15: 46218 | I15: =IF($G15=0,0,IF(I$6<$G15,0,IF(I$6>$H15,1,(I$6-$G15+1)/($H15-$G15+1)))) -> 1 | J15: =IF($G15=0,0,IF(J$6<$G15,0,IF(J$6>$H15,1,(J$6-$G15+1)/($H15-$G15+1)))) -> 1 | K15: =IF($G15=0,0,IF(K$6<$G15,0,IF(K$6>$H15,1,(K$6-$G15+1)/($H15-$G15+1)))) -> 1 | L15: =IF($G15=0,0,IF(L$6<$G15,0,IF(L$6>$H15,1,(L$6-$G15+1)/($H15-$G15+1)))) -> 1 | M15: =IF($G15=0,0,IF(M$6<$G15,0,IF(M$6>$H15,1,(M$6-$G15+1)/($H15-$G15+1)))) -> 1 | N15: =IF($G15=0,0,IF(N$6<$G15,0,IF(N$6>$H15,1,(N$6-$G15+1)/($H15-$G15+1)))) -> 1 | O15: =IF($G15=0,0,IF(O$6<$G15,0,IF(O$6>$H15,1,(O$6-$G15+1)/($H15-$G15+1)))) -> 1 | P15: =IF($G15=0,0,IF(P$6<$G15,0,IF(P$6>$H15,1,(P$6-$G15+1)/($H15-$G15+1)))) -> 1 | ... BO15: =IF($G15=0,0,IF(BO$6<$G15,0,IF(BO$6>$H15,1,(BO$6-$G15+1)/($H15-$G15+1)))) -> 1
B16: 3.2 | C16: REUNIONES RIO ROMANA | D16: 0 días | E16: =VLOOKUP(B16,'Cuadro Control'!C12:J1946,8,FALSE) -> 0 | F16: =IFERROR(E16/$E$8,0) -> 0 | G16: 46218 | H16: 46218 | I16: =IF($G16=0,0,IF(I$6<$G16,0,IF(I$6>$H16,1,(I$6-$G16+1)/($H16-$G16+1)))) -> 1 | J16: =IF($G16=0,0,IF(J$6<$G16,0,IF(J$6>$H16,1,(J$6-$G16+1)/($H16-$G16+1)))) -> 1 | K16: =IF($G16=0,0,IF(K$6<$G16,0,IF(K$6>$H16,1,(K$6-$G16+1)/($H16-$G16+1)))) -> 1 | L16: =IF($G16=0,0,IF(L$6<$G16,0,IF(L$6>$H16,1,(L$6-$G16+1)/($H16-$G16+1)))) -> 1 | M16: =IF($G16=0,0,IF(M$6<$G16,0,IF(M$6>$H16,1,(M$6-$G16+1)/($H16-$G16+1)))) -> 1 | N16: =IF($G16=0,0,IF(N$6<$G16,0,IF(N$6>$H16,1,(N$6-$G16+1)/($H16-$G16+1)))) -> 1 | O16: =IF($G16=0,0,IF(O$6<$G16,0,IF(O$6>$H16,1,(O$6-$G16+1)/($H16-$G16+1)))) -> 1 | P16: =IF($G16=0,0,IF(P$6<$G16,0,IF(P$6>$H16,1,(P$6-$G16+1)/($H16-$G16+1)))) -> 1 | ... BO16: =IF($G16=0,0,IF(BO$6<$G16,0,IF(BO$6>$H16,1,(BO$6-$G16+1)/($H16-$G16+1)))) -> 1
B17: 3.3 | C17: REUNIONES RIO UTKAP | D17: 0 días | E17: =VLOOKUP(B17,'Cuadro Control'!C13:J1947,8,FALSE) -> 0 | F17: =IFERROR(E17/$E$8,0) -> 0 | G17: 46218 | H17: 46218 | I17: =IF($G17=0,0,IF(I$6<$G17,0,IF(I$6>$H17,1,(I$6-$G17+1)/($H17-$G17+1)))) -> 1 | J17: =IF($G17=0,0,IF(J$6<$G17,0,IF(J$6>$H17,1,(J$6-$G17+1)/($H17-$G17+1)))) -> 1 | K17: =IF($G17=0,0,IF(K$6<$G17,0,IF(K$6>$H17,1,(K$6-$G17+1)/($H17-$G17+1)))) -> 1 | L17: =IF($G17=0,0,IF(L$6<$G17,0,IF(L$6>$H17,1,(L$6-$G17+1)/($H17-$G17+1)))) -> 1 | M17: =IF($G17=0,0,IF(M$6<$G17,0,IF(M$6>$H17,1,(M$6-$G17+1)/($H17-$G17+1)))) -> 1 | N17: =IF($G17=0,0,IF(N$6<$G17,0,IF(N$6>$H17,1,(N$6-$G17+1)/($H17-$G17+1)))) -> 1 | O17: =IF($G17=0,0,IF(O$6<$G17,0,IF(O$6>$H17,1,(O$6-$G17+1)/($H17-$G17+1)))) -> 1 | P17: =IF($G17=0,0,IF(P$6<$G17,0,IF(P$6>$H17,1,(P$6-$G17+1)/($H17-$G17+1)))) -> 1 | ... BO17: =IF($G17=0,0,IF(BO$6<$G17,0,IF(BO$6>$H17,1,(BO$6-$G17+1)/($H17-$G17+1)))) -> 1
B18: 3.4 | C18: REUNIONES RIO CALINCHON | D18: 0 días | E18: =VLOOKUP(B18,'Cuadro Control'!C14:J1948,8,FALSE) -> 0 | F18: =IFERROR(E18/$E$8,0) -> 0 | G18: 46218 | H18: 46218 | I18: =IF($G18=0,0,IF(I$6<$G18,0,IF(I$6>$H18,1,(I$6-$G18+1)/($H18-$G18+1)))) -> 1 | J18: =IF($G18=0,0,IF(J$6<$G18,0,IF(J$6>$H18,1,(J$6-$G18+1)/($H18-$G18+1)))) -> 1 | K18: =IF($G18=0,0,IF(K$6<$G18,0,IF(K$6>$H18,1,(K$6-$G18+1)/($H18-$G18+1)))) -> 1 | L18: =IF($G18=0,0,IF(L$6<$G18,0,IF(L$6>$H18,1,(L$6-$G18+1)/($H18-$G18+1)))) -> 1 | M18: =IF($G18=0,0,IF(M$6<$G18,0,IF(M$6>$H18,1,(M$6-$G18+1)/($H18-$G18+1)))) -> 1 | N18: =IF($G18=0,0,IF(N$6<$G18,0,IF(N$6>$H18,1,(N$6-$G18+1)/($H18-$G18+1)))) -> 1 | O18: =IF($G18=0,0,IF(O$6<$G18,0,IF(O$6>$H18,1,(O$6-$G18+1)/($H18-$G18+1)))) -> 1 | P18: =IF($G18=0,0,IF(P$6<$G18,0,IF(P$6>$H18,1,(P$6-$G18+1)/($H18-$G18+1)))) -> 1 | ... BO18: =IF($G18=0,0,IF(BO$6<$G18,0,IF(BO$6>$H18,1,(BO$6-$G18+1)/($H18-$G18+1)))) -> 1
B19: 3.5 | C19: REUNIONES RIO CAÑAVERAL | D19: 0 días | E19: =VLOOKUP(B19,'Cuadro Control'!C15:J1949,8,FALSE) -> 0 | F19: =IFERROR(E19/$E$8,0) -> 0 | G19: 46218 | H19: 46218 | I19: =IF($G19=0,0,IF(I$6<$G19,0,IF(I$6>$H19,1,(I$6-$G19+1)/($H19-$G19+1)))) -> 1 | J19: =IF($G19=0,0,IF(J$6<$G19,0,IF(J$6>$H19,1,(J$6-$G19+1)/($H19-$G19+1)))) -> 1 | K19: =IF($G19=0,0,IF(K$6<$G19,0,IF(K$6>$H19,1,(K$6-$G19+1)/($H19-$G19+1)))) -> 1 | L19: =IF($G19=0,0,IF(L$6<$G19,0,IF(L$6>$H19,1,(L$6-$G19+1)/($H19-$G19+1)))) -> 1 | M19: =IF($G19=0,0,IF(M$6<$G19,0,IF(M$6>$H19,1,(M$6-$G19+1)/($H19-$G19+1)))) -> 1 | N19: =IF($G19=0,0,IF(N$6<$G19,0,IF(N$6>$H19,1,(N$6-$G19+1)/($H19-$G19+1)))) -> 1 | O19: =IF($G19=0,0,IF(O$6<$G19,0,IF(O$6>$H19,1,(O$6-$G19+1)/($H19-$G19+1)))) -> 1 | P19: =IF($G19=0,0,IF(P$6<$G19,0,IF(P$6>$H19,1,(P$6-$G19+1)/($H19-$G19+1)))) -> 1 | ... BO19: =IF($G19=0,0,IF(BO$6<$G19,0,IF(BO$6>$H19,1,(BO$6-$G19+1)/($H19-$G19+1)))) -> 1
B20: 3.6 | C20: REUNIONES RIO KAMUSHIPA | D20: 0 días | E20: =VLOOKUP(B20,'Cuadro Control'!C16:J1950,8,FALSE) -> 0 | F20: =IFERROR(E20/$E$8,0) -> 0 | G20: 46218 | H20: 46218 | I20: =IF($G20=0,0,IF(I$6<$G20,0,IF(I$6>$H20,1,(I$6-$G20+1)/($H20-$G20+1)))) -> 1 | J20: =IF($G20=0,0,IF(J$6<$G20,0,IF(J$6>$H20,1,(J$6-$G20+1)/($H20-$G20+1)))) -> 1 | K20: =IF($G20=0,0,IF(K$6<$G20,0,IF(K$6>$H20,1,(K$6-$G20+1)/($H20-$G20+1)))) -> 1 | L20: =IF($G20=0,0,IF(L$6<$G20,0,IF(L$6>$H20,1,(L$6-$G20+1)/($H20-$G20+1)))) -> 1 | M20: =IF($G20=0,0,IF(M$6<$G20,0,IF(M$6>$H20,1,(M$6-$G20+1)/($H20-$G20+1)))) -> 1 | N20: =IF($G20=0,0,IF(N$6<$G20,0,IF(N$6>$H20,1,(N$6-$G20+1)/($H20-$G20+1)))) -> 1 | O20: =IF($G20=0,0,IF(O$6<$G20,0,IF(O$6>$H20,1,(O$6-$G20+1)/($H20-$G20+1)))) -> 1 | P20: =IF($G20=0,0,IF(P$6<$G20,0,IF(P$6>$H20,1,(P$6-$G20+1)/($H20-$G20+1)))) -> 1 | ... BO20: =IF($G20=0,0,IF(BO$6<$G20,0,IF(BO$6>$H20,1,(BO$6-$G20+1)/($H20-$G20+1)))) -> 1
B21: 3.7 | C21: REUNIONES RIO FLOR DE LA FRONTERA | D21: 0 días | E21: =VLOOKUP(B21,'Cuadro Control'!C17:J1951,8,FALSE) -> 0 | F21: =IFERROR(E21/$E$8,0) -> 0 | G21: 46218 | H21: 46218 | I21: =IF($G21=0,0,IF(I$6<$G21,0,IF(I$6>$H21,1,(I$6-$G21+1)/($H21-$G21+1)))) -> 1 | J21: =IF($G21=0,0,IF(J$6<$G21,0,IF(J$6>$H21,1,(J$6-$G21+1)/($H21-$G21+1)))) -> 1 | K21: =IF($G21=0,0,IF(K$6<$G21,0,IF(K$6>$H21,1,(K$6-$G21+1)/($H21-$G21+1)))) -> 1 | L21: =IF($G21=0,0,IF(L$6<$G21,0,IF(L$6>$H21,1,(L$6-$G21+1)/($H21-$G21+1)))) -> 1 | M21: =IF($G21=0,0,IF(M$6<$G21,0,IF(M$6>$H21,1,(M$6-$G21+1)/($H21-$G21+1)))) -> 1 | N21: =IF($G21=0,0,IF(N$6<$G21,0,IF(N$6>$H21,1,(N$6-$G21+1)/($H21-$G21+1)))) -> 1 | O21: =IF($G21=0,0,IF(O$6<$G21,0,IF(O$6>$H21,1,(O$6-$G21+1)/($H21-$G21+1)))) -> 1 | P21: =IF($G21=0,0,IF(P$6<$G21,0,IF(P$6>$H21,1,(P$6-$G21+1)/($H21-$G21+1)))) -> 1 | ... BO21: =IF($G21=0,0,IF(BO$6<$G21,0,IF(BO$6>$H21,1,(BO$6-$G21+1)/($H21-$G21+1)))) -> 1
B22: 3.8 | C22: REUNIONES RIO JAIKA KALINCHON | D22: 0 días | E22: =VLOOKUP(B22,'Cuadro Control'!C18:J1952,8,FALSE) -> 0 | F22: =IFERROR(E22/$E$8,0) -> 0 | G22: 46218 | H22: 46218 | I22: =IF($G22=0,0,IF(I$6<$G22,0,IF(I$6>$H22,1,(I$6-$G22+1)/($H22-$G22+1)))) -> 1 | J22: =IF($G22=0,0,IF(J$6<$G22,0,IF(J$6>$H22,1,(J$6-$G22+1)/($H22-$G22+1)))) -> 1 | K22: =IF($G22=0,0,IF(K$6<$G22,0,IF(K$6>$H22,1,(K$6-$G22+1)/($H22-$G22+1)))) -> 1 | L22: =IF($G22=0,0,IF(L$6<$G22,0,IF(L$6>$H22,1,(L$6-$G22+1)/($H22-$G22+1)))) -> 1 | M22: =IF($G22=0,0,IF(M$6<$G22,0,IF(M$6>$H22,1,(M$6-$G22+1)/($H22-$G22+1)))) -> 1 | N22: =IF($G22=0,0,IF(N$6<$G22,0,IF(N$6>$H22,1,(N$6-$G22+1)/($H22-$G22+1)))) -> 1 | O22: =IF($G22=0,0,IF(O$6<$G22,0,IF(O$6>$H22,1,(O$6-$G22+1)/($H22-$G22+1)))) -> 1 | P22: =IF($G22=0,0,IF(P$6<$G22,0,IF(P$6>$H22,1,(P$6-$G22+1)/($H22-$G22+1)))) -> 1 | ... BO22: =IF($G22=0,0,IF(BO$6<$G22,0,IF(BO$6>$H22,1,(BO$6-$G22+1)/($H22-$G22+1)))) -> 1
B23: 3.9 | C23: REUNIONES RIO MASHUMANA | D23: 0 días | E23: =VLOOKUP(B23,'Cuadro Control'!C19:J1953,8,FALSE) -> 0 | F23: =IFERROR(E23/$E$8,0) -> 0 | G23: 46218 | H23: 46218 | I23: =IF($G23=0,0,IF(I$6<$G23,0,IF(I$6>$H23,1,(I$6-$G23+1)/($H23-$G23+1)))) -> 1 | J23: =IF($G23=0,0,IF(J$6<$G23,0,IF(J$6>$H23,1,(J$6-$G23+1)/($H23-$G23+1)))) -> 1 | K23: =IF($G23=0,0,IF(K$6<$G23,0,IF(K$6>$H23,1,(K$6-$G23+1)/($H23-$G23+1)))) -> 1 | L23: =IF($G23=0,0,IF(L$6<$G23,0,IF(L$6>$H23,1,(L$6-$G23+1)/($H23-$G23+1)))) -> 1 | M23: =IF($G23=0,0,IF(M$6<$G23,0,IF(M$6>$H23,1,(M$6-$G23+1)/($H23-$G23+1)))) -> 1 | N23: =IF($G23=0,0,IF(N$6<$G23,0,IF(N$6>$H23,1,(N$6-$G23+1)/($H23-$G23+1)))) -> 1 | O23: =IF($G23=0,0,IF(O$6<$G23,0,IF(O$6>$H23,1,(O$6-$G23+1)/($H23-$G23+1)))) -> 1 | P23: =IF($G23=0,0,IF(P$6<$G23,0,IF(P$6>$H23,1,(P$6-$G23+1)/($H23-$G23+1)))) -> 1 | ... BO23: =IF($G23=0,0,IF(BO$6<$G23,0,IF(BO$6>$H23,1,(BO$6-$G23+1)/($H23-$G23+1)))) -> 1
B24: 3.10 | C24: REUNIONES RIO MASHUMANA WANE | D24: 0 días | E24: =VLOOKUP(B24,'Cuadro Control'!C20:J1954,8,FALSE) -> 0 | F24: =IFERROR(E24/$E$8,0) -> 0 | G24: 46218 | H24: 46218 | I24: =IF($G24=0,0,IF(I$6<$G24,0,IF(I$6>$H24,1,(I$6-$G24+1)/($H24-$G24+1)))) -> 1 | J24: =IF($G24=0,0,IF(J$6<$G24,0,IF(J$6>$H24,1,(J$6-$G24+1)/($H24-$G24+1)))) -> 1 | K24: =IF($G24=0,0,IF(K$6<$G24,0,IF(K$6>$H24,1,(K$6-$G24+1)/($H24-$G24+1)))) -> 1 | L24: =IF($G24=0,0,IF(L$6<$G24,0,IF(L$6>$H24,1,(L$6-$G24+1)/($H24-$G24+1)))) -> 1 | M24: =IF($G24=0,0,IF(M$6<$G24,0,IF(M$6>$H24,1,(M$6-$G24+1)/($H24-$G24+1)))) -> 1 | N24: =IF($G24=0,0,IF(N$6<$G24,0,IF(N$6>$H24,1,(N$6-$G24+1)/($H24-$G24+1)))) -> 1 | O24: =IF($G24=0,0,IF(O$6<$G24,0,IF(O$6>$H24,1,(O$6-$G24+1)/($H24-$G24+1)))) -> 1 | P24: =IF($G24=0,0,IF(P$6<$G24,0,IF(P$6>$H24,1,(P$6-$G24+1)/($H24-$G24+1)))) -> 1 | ... BO24: =IF($G24=0,0,IF(BO$6<$G24,0,IF(BO$6>$H24,1,(BO$6-$G24+1)/($H24-$G24+1)))) -> 1
B25: 3.11 | C25: REUNIONES RIO MATAJUNAY | D25: 0 días | E25: =VLOOKUP(B25,'Cuadro Control'!C21:J1955,8,FALSE) -> 0 | F25: =IFERROR(E25/$E$8,0) -> 0 | G25: 46218 | H25: 46218 | I25: =IF($G25=0,0,IF(I$6<$G25,0,IF(I$6>$H25,1,(I$6-$G25+1)/($H25-$G25+1)))) -> 1 | J25: =IF($G25=0,0,IF(J$6<$G25,0,IF(J$6>$H25,1,(J$6-$G25+1)/($H25-$G25+1)))) -> 1 | K25: =IF($G25=0,0,IF(K$6<$G25,0,IF(K$6>$H25,1,(K$6-$G25+1)/($H25-$G25+1)))) -> 1 | L25: =IF($G25=0,0,IF(L$6<$G25,0,IF(L$6>$H25,1,(L$6-$G25+1)/($H25-$G25+1)))) -> 1 | M25: =IF($G25=0,0,IF(M$6<$G25,0,IF(M$6>$H25,1,(M$6-$G25+1)/($H25-$G25+1)))) -> 1 | N25: =IF($G25=0,0,IF(N$6<$G25,0,IF(N$6>$H25,1,(N$6-$G25+1)/($H25-$G25+1)))) -> 1 | O25: =IF($G25=0,0,IF(O$6<$G25,0,IF(O$6>$H25,1,(O$6-$G25+1)/($H25-$G25+1)))) -> 1 | P25: =IF($G25=0,0,IF(P$6<$G25,0,IF(P$6>$H25,1,(P$6-$G25+1)/($H25-$G25+1)))) -> 1 | ... BO25: =IF($G25=0,0,IF(BO$6<$G25,0,IF(BO$6>$H25,1,(BO$6-$G25+1)/($H25-$G25+1)))) -> 1
B26: 3.12 | C26: REUNIONES RIO MANNAJUYAY | D26: 0 días | E26: =VLOOKUP(B26,'Cuadro Control'!C22:J1956,8,FALSE) -> 0 | F26: =IFERROR(E26/$E$8,0) -> 0 | G26: 46218 | H26: 46218 | I26: =IF($G26=0,0,IF(I$6<$G26,0,IF(I$6>$H26,1,(I$6-$G26+1)/($H26-$G26+1)))) -> 1 | J26: =IF($G26=0,0,IF(J$6<$G26,0,IF(J$6>$H26,1,(J$6-$G26+1)/($H26-$G26+1)))) -> 1 | K26: =IF($G26=0,0,IF(K$6<$G26,0,IF(K$6>$H26,1,(K$6-$G26+1)/($H26-$G26+1)))) -> 1 | L26: =IF($G26=0,0,IF(L$6<$G26,0,IF(L$6>$H26,1,(L$6-$G26+1)/($H26-$G26+1)))) -> 1 | M26: =IF($G26=0,0,IF(M$6<$G26,0,IF(M$6>$H26,1,(M$6-$G26+1)/($H26-$G26+1)))) -> 1 | N26: =IF($G26=0,0,IF(N$6<$G26,0,IF(N$6>$H26,1,(N$6-$G26+1)/($H26-$G26+1)))) -> 1 | O26: =IF($G26=0,0,IF(O$6<$G26,0,IF(O$6>$H26,1,(O$6-$G26+1)/($H26-$G26+1)))) -> 1 | P26: =IF($G26=0,0,IF(P$6<$G26,0,IF(P$6>$H26,1,(P$6-$G26+1)/($H26-$G26+1)))) -> 1 | ... BO26: =IF($G26=0,0,IF(BO$6<$G26,0,IF(BO$6>$H26,1,(BO$6-$G26+1)/($H26-$G26+1)))) -> 1
... B28: 3.14 | C28: REUNIONES RIO JAMUCHERRU | D28: 0 días | E28: =VLOOKUP(B28,'Cuadro Control'!C24:J1958,8,FALSE) -> 0 | F28: =IFERROR(E28/$E$8,0) -> 0 | G28: 46252 | H28: 46252 | I28: =IF($G28=0,0,IF(I$6<$G28,0,IF(I$6>$H28,1,(I$6-$G28+1)/($H28-$G28+1)))) -> 0 | J28: =IF($G28=0,0,IF(J$6<$G28,0,IF(J$6>$H28,1,(J$6-$G28+1)/($H28-$G28+1)))) -> 0 | K28: =IF($G28=0,0,IF(K$6<$G28,0,IF(K$6>$H28,1,(K$6-$G28+1)/($H28-$G28+1)))) -> 0 | L28: =IF($G28=0,0,IF(L$6<$G28,0,IF(L$6>$H28,1,(L$6-$G28+1)/($H28-$G28+1)))) -> 0 | M28: =IF($G28=0,0,IF(M$6<$G28,0,IF(M$6>$H28,1,(M$6-$G28+1)/($H28-$G28+1)))) -> 0 | N28: =IF($G28=0,0,IF(N$6<$G28,0,IF(N$6>$H28,1,(N$6-$G28+1)/($H28-$G28+1)))) -> 0 | O28: =IF($G28=0,0,IF(O$6<$G28,0,IF(O$6>$H28,1,(O$6-$G28+1)/($H28-$G28+1)))) -> 1 | P28: =IF($G28=0,0,IF(P$6<$G28,0,IF(P$6>$H28,1,(P$6-$G28+1)/($H28-$G28+1)))) -> 1 | ... BO28: =IF($G28=0,0,IF(BO$6<$G28,0,IF(BO$6>$H28,1,(BO$6-$G28+1)/($H28-$G28+1)))) -> 1
B29: 4 | C29: PUBLICACIÓN DE VACANTES/CONTRATACIÓN DE PERSONAL | D29: 20 días | E29: =VLOOKUP(B29,'Cuadro Control'!C25:J1959,8,FALSE) -> 0 | F29: =IFERROR(E29/$E$8,0) -> 0 | G29: 46218 | H29: 46239 | I29: =IF($G29=0,0,IF(I$6<$G29,0,IF(I$6>$H29,1,(I$6-$G29+1)/($H29-$G29+1)))) -> 0.045454545 | J29: =IF($G29=0,0,IF(J$6<$G29,0,IF(J$6>$H29,1,(J$6-$G29+1)/($H29-$G29+1)))) -> 0.13636364 | K29: =IF($G29=0,0,IF(K$6<$G29,0,IF(K$6>$H29,1,(K$6-$G29+1)/($H29-$G29+1)))) -> 0.45454545 | L29: =IF($G29=0,0,IF(L$6<$G29,0,IF(L$6>$H29,1,(L$6-$G29+1)/($H29-$G29+1)))) -> 0.77272727 | M29: =IF($G29=0,0,IF(M$6<$G29,0,IF(M$6>$H29,1,(M$6-$G29+1)/($H29-$G29+1)))) -> 1 | N29: =IF($G29=0,0,IF(N$6<$G29,0,IF(N$6>$H29,1,(N$6-$G29+1)/($H29-$G29+1)))) -> 1 | O29: =IF($G29=0,0,IF(O$6<$G29,0,IF(O$6>$H29,1,(O$6-$G29+1)/($H29-$G29+1)))) -> 1 | P29: =IF($G29=0,0,IF(P$6<$G29,0,IF(P$6>$H29,1,(P$6-$G29+1)/($H29-$G29+1)))) -> 1 | ... BO29: =IF($G29=0,0,IF(BO$6<$G29,0,IF(BO$6>$H29,1,(BO$6-$G29+1)/($H29-$G29+1)))) -> 1
B30: 5 | C30: SUMINISTRO DE MATERIALES | D30: 21 días | E30: =VLOOKUP(B30,'Cuadro Control'!C26:J1960,8,FALSE) -> 0 | F30: =IFERROR(E30/$E$8,0) -> 0 | G30: 46240 | H30: 46273 | I30: =IF($G30=0,0,IF(I$6<$G30,0,IF(I$6>$H30,1,(I$6-$G30+1)/($H30-$G30+1)))) -> 0 | J30: =IF($G30=0,0,IF(J$6<$G30,0,IF(J$6>$H30,1,(J$6-$G30+1)/($H30-$G30+1)))) -> 0 | K30: =IF($G30=0,0,IF(K$6<$G30,0,IF(K$6>$H30,1,(K$6-$G30+1)/($H30-$G30+1)))) -> 0 | L30: =IF($G30=0,0,IF(L$6<$G30,0,IF(L$6>$H30,1,(L$6-$G30+1)/($H30-$G30+1)))) -> 0 | M30: =IF($G30=0,0,IF(M$6<$G30,0,IF(M$6>$H30,1,(M$6-$G30+1)/($H30-$G30+1)))) -> 0.058823529 | N30: =IF($G30=0,0,IF(N$6<$G30,0,IF(N$6>$H30,1,(N$6-$G30+1)/($H30-$G30+1)))) -> 0.26470588 | O30: =IF($G30=0,0,IF(O$6<$G30,0,IF(O$6>$H30,1,(O$6-$G30+1)/($H30-$G30+1)))) -> 0.47058824 | P30: =IF($G30=0,0,IF(P$6<$G30,0,IF(P$6>$H30,1,(P$6-$G30+1)/($H30-$G30+1)))) -> 0.67647059 | ... BO30: =IF($G30=0,0,IF(BO$6<$G30,0,IF(BO$6>$H30,1,(BO$6-$G30+1)/($H30-$G30+1)))) -> 1
B31: 5.1 | C31: SUMINISTRO DE MATERIALES CIVILES: ANCHOR CAGE (CLIENTE) | D31: 14 días | E31: =VLOOKUP(B31,'Cuadro Control'!C27:J1961,8,FALSE) -> 0 | F31: =IFERROR(E31/$E$30,0) -> 0 | G31: 46240 | H31: 46258 | I31: =IF($G31=0,0,IF(I$6<$G31,0,IF(I$6>$H31,1,(I$6-$G31+1)/($H31-$G31+1)))) -> 0 | J31: =IF($G31=0,0,IF(J$6<$G31,0,IF(J$6>$H31,1,(J$6-$G31+1)/($H31-$G31+1)))) -> 0 | K31: =IF($G31=0,0,IF(K$6<$G31,0,IF(K$6>$H31,1,(K$6-$G31+1)/($H31-$G31+1)))) -> 0 | L31: =IF($G31=0,0,IF(L$6<$G31,0,IF(L$6>$H31,1,(L$6-$G31+1)/($H31-$G31+1)))) -> 0 | M31: =IF($G31=0,0,IF(M$6<$G31,0,IF(M$6>$H31,1,(M$6-$G31+1)/($H31-$G31+1)))) -> 0.10526316 | N31: =IF($G31=0,0,IF(N$6<$G31,0,IF(N$6>$H31,1,(N$6-$G31+1)/($H31-$G31+1)))) -> 0.47368421 | O31: =IF($G31=0,0,IF(O$6<$G31,0,IF(O$6>$H31,1,(O$6-$G31+1)/($H31-$G31+1)))) -> 0.84210526 | P31: =IF($G31=0,0,IF(P$6<$G31,0,IF(P$6>$H31,1,(P$6-$G31+1)/($H31-$G31+1)))) -> 1 | ... BO31: =IF($G31=0,0,IF(BO$6<$G31,0,IF(BO$6>$H31,1,(BO$6-$G31+1)/($H31-$G31+1)))) -> 1
B32: 5.2 | C32: SUMINISTRO DE MATERIALES CIVILES: ACEROS DE REFUERSO | D32: 7 días | E32: =VLOOKUP(B32,'Cuadro Control'!C28:J1962,8,FALSE) -> 0 | F32: =IFERROR(E32/$E$30,0) -> 0 | G32: 46258 | H32: 46273 | I32: =IF($G32=0,0,IF(I$6<$G32,0,IF(I$6>$H32,1,(I$6-$G32+1)/($H32-$G32+1)))) -> 0 | J32: =IF($G32=0,0,IF(J$6<$G32,0,IF(J$6>$H32,1,(J$6-$G32+1)/($H32-$G32+1)))) -> 0 | K32: =IF($G32=0,0,IF(K$6<$G32,0,IF(K$6>$H32,1,(K$6-$G32+1)/($H32-$G32+1)))) -> 0 | L32: =IF($G32=0,0,IF(L$6<$G32,0,IF(L$6>$H32,1,(L$6-$G32+1)/($H32-$G32+1)))) -> 0 | M32: =IF($G32=0,0,IF(M$6<$G32,0,IF(M$6>$H32,1,(M$6-$G32+1)/($H32-$G32+1)))) -> 0 | N32: =IF($G32=0,0,IF(N$6<$G32,0,IF(N$6>$H32,1,(N$6-$G32+1)/($H32-$G32+1)))) -> 0 | O32: =IF($G32=0,0,IF(O$6<$G32,0,IF(O$6>$H32,1,(O$6-$G32+1)/($H32-$G32+1)))) -> 0 | P32: =IF($G32=0,0,IF(P$6<$G32,0,IF(P$6>$H32,1,(P$6-$G32+1)/($H32-$G32+1)))) -> 0.3125 | ... BO32: =IF($G32=0,0,IF(BO$6<$G32,0,IF(BO$6>$H32,1,(BO$6-$G32+1)/($H32-$G32+1)))) -> 1
B33: 6 | C33: HITO 2: INICIO DE ACTIVIDADES EN CAMPO | D33: 0 días | E33: =VLOOKUP(B33,'Cuadro Control'!C29:J1963,8,FALSE) -> 0 | F33: =IFERROR(E33/$E$8,0) -> 0 | G33: 46239 | H33: 46239 | I33: =IF($G33=0,0,IF(I$6<$G33,0,IF(I$6>$H33,1,(I$6-$G33+1)/($H33-$G33+1)))) -> 0 | J33: =IF($G33=0,0,IF(J$6<$G33,0,IF(J$6>$H33,1,(J$6-$G33+1)/($H33-$G33+1)))) -> 0 | K33: =IF($G33=0,0,IF(K$6<$G33,0,IF(K$6>$H33,1,(K$6-$G33+1)/($H33-$G33+1)))) -> 0 | L33: =IF($G33=0,0,IF(L$6<$G33,0,IF(L$6>$H33,1,(L$6-$G33+1)/($H33-$G33+1)))) -> 0 | M33: =IF($G33=0,0,IF(M$6<$G33,0,IF(M$6>$H33,1,(M$6-$G33+1)/($H33-$G33+1)))) -> 1 | N33: =IF($G33=0,0,IF(N$6<$G33,0,IF(N$6>$H33,1,(N$6-$G33+1)/($H33-$G33+1)))) -> 1 | O33: =IF($G33=0,0,IF(O$6<$G33,0,IF(O$6>$H33,1,(O$6-$G33+1)/($H33-$G33+1)))) -> 1 | P33: =IF($G33=0,0,IF(P$6<$G33,0,IF(P$6>$H33,1,(P$6-$G33+1)/($H33-$G33+1)))) -> 1 | ... BO33: =IF($G33=0,0,IF(BO$6<$G33,0,IF(BO$6>$H33,1,(BO$6-$G33+1)/($H33-$G33+1)))) -> 1
B34: 7 | C34: PISCINA INDUSTRIAL | D34: 32 días | E34: =SUM(E35:E38) -> 4.6179078e+08 | F34: =IFERROR(E34/$E$8,0) -> 0.0022153966 | G34: 46240 | H34: 46276 | I34: =SUMPRODUCT($F35:$F38,I35:I38) -> 0 | J34: =SUMPRODUCT($F35:$F38,J35:J38) -> 0 | K34: =SUMPRODUCT($F35:$F38,K35:K38) -> 0 | L34: =SUMPRODUCT($F35:$F38,L35:L38) -> 0 | M34: =SUMPRODUCT($F35:$F38,M35:M38) -> 0 | N34: =SUMPRODUCT($F35:$F38,N35:N38) -> 0 | O34: =SUMPRODUCT($F35:$F38,O35:O38) -> 0 | P34: =SUMPRODUCT($F35:$F38,P35:P38) -> 0 | ... BO34: =SUMPRODUCT($F35:$F38,BO35:BO38) -> 1
B35: 7.1 | C35: MOVIMIENTO DE TIERRAS Y RECONFORMACION PISCINA INDUSTRIAL | D35: 14 días | E35: =VLOOKUP(B35,'Cuadro Control'!C31:J1965,8,FALSE) -> 0 | F35: =IFERROR(E35/$E$34,0) -> 0 | G35: 46240 | H35: 46258 | I35: =IF($G35=0,0,IF(I$6<$G35,0,IF(I$6>$H35,1,(I$6-$G35+1)/($H35-$G35+1)))) -> 0 | J35: =IF($G35=0,0,IF(J$6<$G35,0,IF(J$6>$H35,1,(J$6-$G35+1)/($H35-$G35+1)))) -> 0 | K35: =IF($G35=0,0,IF(K$6<$G35,0,IF(K$6>$H35,1,(K$6-$G35+1)/($H35-$G35+1)))) -> 0 | L35: =IF($G35=0,0,IF(L$6<$G35,0,IF(L$6>$H35,1,(L$6-$G35+1)/($H35-$G35+1)))) -> 0 | M35: =IF($G35=0,0,IF(M$6<$G35,0,IF(M$6>$H35,1,(M$6-$G35+1)/($H35-$G35+1)))) -> 0.10526316 | N35: =IF($G35=0,0,IF(N$6<$G35,0,IF(N$6>$H35,1,(N$6-$G35+1)/($H35-$G35+1)))) -> 0.47368421 | O35: =IF($G35=0,0,IF(O$6<$G35,0,IF(O$6>$H35,1,(O$6-$G35+1)/($H35-$G35+1)))) -> 0.84210526 | P35: =IF($G35=0,0,IF(P$6<$G35,0,IF(P$6>$H35,1,(P$6-$G35+1)/($H35-$G35+1)))) -> 1 | ... BO35: =IF($G35=0,0,IF(BO$6<$G35,0,IF(BO$6>$H35,1,(BO$6-$G35+1)/($H35-$G35+1)))) -> 1
B36: 7.2 | C36: INSTALACION DE GEOMEMBRANA PISCINA INDUSTRIAL | D36: 10 días | E36: =VLOOKUP(B36,'Cuadro Control'!C32:J1966,8,FALSE) -> 0 | F36: =IFERROR(E36/$E$34,0) -> 0 | G36: 46258 | H36: 46268 | I36: =IF($G36=0,0,IF(I$6<$G36,0,IF(I$6>$H36,1,(I$6-$G36+1)/($H36-$G36+1)))) -> 0 | J36: =IF($G36=0,0,IF(J$6<$G36,0,IF(J$6>$H36,1,(J$6-$G36+1)/($H36-$G36+1)))) -> 0 | K36: =IF($G36=0,0,IF(K$6<$G36,0,IF(K$6>$H36,1,(K$6-$G36+1)/($H36-$G36+1)))) -> 0 | L36: =IF($G36=0,0,IF(L$6<$G36,0,IF(L$6>$H36,1,(L$6-$G36+1)/($H36-$G36+1)))) -> 0 | M36: =IF($G36=0,0,IF(M$6<$G36,0,IF(M$6>$H36,1,(M$6-$G36+1)/($H36-$G36+1)))) -> 0 | N36: =IF($G36=0,0,IF(N$6<$G36,0,IF(N$6>$H36,1,(N$6-$G36+1)/($H36-$G36+1)))) -> 0 | O36: =IF($G36=0,0,IF(O$6<$G36,0,IF(O$6>$H36,1,(O$6-$G36+1)/($H36-$G36+1)))) -> 0 | P36: =IF($G36=0,0,IF(P$6<$G36,0,IF(P$6>$H36,1,(P$6-$G36+1)/($H36-$G36+1)))) -> 0.45454545 | ... BO36: =IF($G36=0,0,IF(BO$6<$G36,0,IF(BO$6>$H36,1,(BO$6-$G36+1)/($H36-$G36+1)))) -> 1
B37: 7.3 | C37: CONSTRUCCION DE CERRAMIENTO EN ALAMBRE DE PUA PISCINA INDUSTRIAL | D37: 14 días | E37: =VLOOKUP(B37,'Cuadro Control'!C33:J1967,8,FALSE) -> 0 | F37: =IFERROR(E37/$E$34,0) -> 0 | G37: 46245 | H37: 46261 | I37: =IF($G37=0,0,IF(I$6<$G37,0,IF(I$6>$H37,1,(I$6-$G37+1)/($H37-$G37+1)))) -> 0 | J37: =IF($G37=0,0,IF(J$6<$G37,0,IF(J$6>$H37,1,(J$6-$G37+1)/($H37-$G37+1)))) -> 0 | K37: =IF($G37=0,0,IF(K$6<$G37,0,IF(K$6>$H37,1,(K$6-$G37+1)/($H37-$G37+1)))) -> 0 | L37: =IF($G37=0,0,IF(L$6<$G37,0,IF(L$6>$H37,1,(L$6-$G37+1)/($H37-$G37+1)))) -> 0 | M37: =IF($G37=0,0,IF(M$6<$G37,0,IF(M$6>$H37,1,(M$6-$G37+1)/($H37-$G37+1)))) -> 0 | N37: =IF($G37=0,0,IF(N$6<$G37,0,IF(N$6>$H37,1,(N$6-$G37+1)/($H37-$G37+1)))) -> 0.23529412 | O37: =IF($G37=0,0,IF(O$6<$G37,0,IF(O$6>$H37,1,(O$6-$G37+1)/($H37-$G37+1)))) -> 0.64705882 | P37: =IF($G37=0,0,IF(P$6<$G37,0,IF(P$6>$H37,1,(P$6-$G37+1)/($H37-$G37+1)))) -> 1 | ... BO37: =IF($G37=0,0,IF(BO$6<$G37,0,IF(BO$6>$H37,1,(BO$6-$G37+1)/($H37-$G37+1)))) -> 1
B38: 7.4 | C38: CONSTRUCCION CUNETA PERIMETRAL PISCINA INDUSTRIAL | D38: 8 días | E38: =VLOOKUP(B38,'Cuadro Control'!C34:J1968,8,FALSE) -> 4.6179078e+08 | F38: =IFERROR(E38/$E$34,0) -> 1 | G38: 46268 | H38: 46276 | I38: =IF($G38=0,0,IF(I$6<$G38,0,IF(I$6>$H38,1,(I$6-$G38+1)/($H38-$G38+1)))) -> 0 | J38: =IF($G38=0,0,IF(J$6<$G38,0,IF(J$6>$H38,1,(J$6-$G38+1)/($H38-$G38+1)))) -> 0 | K38: =IF($G38=0,0,IF(K$6<$G38,0,IF(K$6>$H38,1,(K$6-$G38+1)/($H38-$G38+1)))) -> 0 | L38: =IF($G38=0,0,IF(L$6<$G38,0,IF(L$6>$H38,1,(L$6-$G38+1)/($H38-$G38+1)))) -> 0 | M38: =IF($G38=0,0,IF(M$6<$G38,0,IF(M$6>$H38,1,(M$6-$G38+1)/($H38-$G38+1)))) -> 0 | N38: =IF($G38=0,0,IF(N$6<$G38,0,IF(N$6>$H38,1,(N$6-$G38+1)/($H38-$G38+1)))) -> 0 | O38: =IF($G38=0,0,IF(O$6<$G38,0,IF(O$6>$H38,1,(O$6-$G38+1)/($H38-$G38+1)))) -> 0 | P38: =IF($G38=0,0,IF(P$6<$G38,0,IF(P$6>$H38,1,(P$6-$G38+1)/($H38-$G38+1)))) -> 0 | ... BO38: =IF($G38=0,0,IF(BO$6<$G38,0,IF(BO$6>$H38,1,(BO$6-$G38+1)/($H38-$G38+1)))) -> 1
B39: 8 | C39: ZONAS DE CAMPAMENTOS - FAENAS | D39: 305 días | E39: =SUM(E40:E43) -> 8.3636378e+09 | F39: =IFERROR(E39/$E$8,0) -> 0.040123744 | G39: 46256 | H39: 46596 | I39: =SUMPRODUCT($F40:$F43,I40:I43) -> 0 | J39: =SUMPRODUCT($F40:$F43,J40:J43) -> 0 | K39: =SUMPRODUCT($F40:$F43,K40:K43) -> 0 | L39: =SUMPRODUCT($F40:$F43,L40:L43) -> 0 | M39: =SUMPRODUCT($F40:$F43,M40:M43) -> 0 | N39: =SUMPRODUCT($F40:$F43,N40:N43) -> 0 | O39: =SUMPRODUCT($F40:$F43,O40:O43) -> 0 | P39: =SUMPRODUCT($F40:$F43,P40:P43) -> 0.00042802934 | ... BO39: =SUMPRODUCT($F40:$F43,BO40:BO43) -> 1
B40: 8.1 | C40: CONFORMACIÓN DEL AREA ZONAS DE CAMPAMENTOS - FAENAS | D40: 14 días | E40: =VLOOKUP(B40,'Cuadro Control'!C36:J1970,8,FALSE) -> 8694000 | F40: =IFERROR(E40/$E$39,0) -> 0.0010394998 | G40: 46256 | H40: 46272 | I40: =IF($G40=0,0,IF(I$6<$G40,0,IF(I$6>$H40,1,(I$6-$G40+1)/($H40-$G40+1)))) -> 0 | J40: =IF($G40=0,0,IF(J$6<$G40,0,IF(J$6>$H40,1,(J$6-$G40+1)/($H40-$G40+1)))) -> 0 | K40: =IF($G40=0,0,IF(K$6<$G40,0,IF(K$6>$H40,1,(K$6-$G40+1)/($H40-$G40+1)))) -> 0 | L40: =IF($G40=0,0,IF(L$6<$G40,0,IF(L$6>$H40,1,(L$6-$G40+1)/($H40-$G40+1)))) -> 0 | M40: =IF($G40=0,0,IF(M$6<$G40,0,IF(M$6>$H40,1,(M$6-$G40+1)/($H40-$G40+1)))) -> 0 | N40: =IF($G40=0,0,IF(N$6<$G40,0,IF(N$6>$H40,1,(N$6-$G40+1)/($H40-$G40+1)))) -> 0 | O40: =IF($G40=0,0,IF(O$6<$G40,0,IF(O$6>$H40,1,(O$6-$G40+1)/($H40-$G40+1)))) -> 0 | P40: =IF($G40=0,0,IF(P$6<$G40,0,IF(P$6>$H40,1,(P$6-$G40+1)/($H40-$G40+1)))) -> 0.41176471 | ... BO40: =IF($G40=0,0,IF(BO$6<$G40,0,IF(BO$6>$H40,1,(BO$6-$G40+1)/($H40-$G40+1)))) -> 1
B41: 8.2 | C41: INSTALACIÓN DE CONTENEDORES Y EQUIPOS ZONAS DE CAMPAMENTOS - FAENAS | D41: 10 días | E41: =VLOOKUP(B41,'Cuadro Control'!C37:J1971,8,FALSE) -> 5260179.1 | F41: =IFERROR(E41/$E$39,0) -> 0.00062893435 | G41: 46272 | H41: 46282 | I41: =IF($G41=0,0,IF(I$6<$G41,0,IF(I$6>$H41,1,(I$6-$G41+1)/($H41-$G41+1)))) -> 0 | J41: =IF($G41=0,0,IF(J$6<$G41,0,IF(J$6>$H41,1,(J$6-$G41+1)/($H41-$G41+1)))) -> 0 | K41: =IF($G41=0,0,IF(K$6<$G41,0,IF(K$6>$H41,1,(K$6-$G41+1)/($H41-$G41+1)))) -> 0 | L41: =IF($G41=0,0,IF(L$6<$G41,0,IF(L$6>$H41,1,(L$6-$G41+1)/($H41-$G41+1)))) -> 0 | M41: =IF($G41=0,0,IF(M$6<$G41,0,IF(M$6>$H41,1,(M$6-$G41+1)/($H41-$G41+1)))) -> 0 | N41: =IF($G41=0,0,IF(N$6<$G41,0,IF(N$6>$H41,1,(N$6-$G41+1)/($H41-$G41+1)))) -> 0 | O41: =IF($G41=0,0,IF(O$6<$G41,0,IF(O$6>$H41,1,(O$6-$G41+1)/($H41-$G41+1)))) -> 0 | P41: =IF($G41=0,0,IF(P$6<$G41,0,IF(P$6>$H41,1,(P$6-$G41+1)/($H41-$G41+1)))) -> 0 | ... BO41: =IF($G41=0,0,IF(BO$6<$G41,0,IF(BO$6>$H41,1,(BO$6-$G41+1)/($H41-$G41+1)))) -> 1
B42: 8.3 | C42: INSTALACIÓN DE LAS FACILIDADES ELECTRICAS E HIDRÚALICAS DE LOS CONTENEDORES ZONAS DE CAMPAMENTOS - FAENAS | D42: 8 días | E42: =VLOOKUP(B42,'Cuadro Control'!C38:J1972,8,FALSE) -> 70893128 | F42: =IFERROR(E42/$E$39,0) -> 0.0084763508 | G42: 46282 | H42: 46290 | I42: =IF($G42=0,0,IF(I$6<$G42,0,IF(I$6>$H42,1,(I$6-$G42+1)/($H42-$G42+1)))) -> 0 | J42: =IF($G42=0,0,IF(J$6<$G42,0,IF(J$6>$H42,1,(J$6-$G42+1)/($H42-$G42+1)))) -> 0 | K42: =IF($G42=0,0,IF(K$6<$G42,0,IF(K$6>$H42,1,(K$6-$G42+1)/($H42-$G42+1)))) -> 0 | L42: =IF($G42=0,0,IF(L$6<$G42,0,IF(L$6>$H42,1,(L$6-$G42+1)/($H42-$G42+1)))) -> 0 | M42: =IF($G42=0,0,IF(M$6<$G42,0,IF(M$6>$H42,1,(M$6-$G42+1)/($H42-$G42+1)))) -> 0 | N42: =IF($G42=0,0,IF(N$6<$G42,0,IF(N$6>$H42,1,(N$6-$G42+1)/($H42-$G42+1)))) -> 0 | O42: =IF($G42=0,0,IF(O$6<$G42,0,IF(O$6>$H42,1,(O$6-$G42+1)/($H42-$G42+1)))) -> 0 | P42: =IF($G42=0,0,IF(P$6<$G42,0,IF(P$6>$H42,1,(P$6-$G42+1)/($H42-$G42+1)))) -> 0 | ... BO42: =IF($G42=0,0,IF(BO$6<$G42,0,IF(BO$6>$H42,1,(BO$6-$G42+1)/($H42-$G42+1)))) -> 1
B43: 8.4 | C43: ADMINISTRACIÓN Y MANTENIMIENTO DE CAMPAMENTOS | D43: 280 días | E43: =VLOOKUP(B43,'Cuadro Control'!C40:J1973,8,FALSE) -> 8.2787905e+09 | F43: =IFERROR(E43/$E$39,0) -> 0.98985521 | G43: 46283 | H43: 46596 | I43: =IF($G43=0,0,IF(I$6<$G43,0,IF(I$6>$H43,1,(I$6-$G43+1)/($H43-$G43+1)))) -> 0 | J43: =IF($G43=0,0,IF(J$6<$G43,0,IF(J$6>$H43,1,(J$6-$G43+1)/($H43-$G43+1)))) -> 0 | K43: =IF($G43=0,0,IF(K$6<$G43,0,IF(K$6>$H43,1,(K$6-$G43+1)/($H43-$G43+1)))) -> 0 | L43: =IF($G43=0,0,IF(L$6<$G43,0,IF(L$6>$H43,1,(L$6-$G43+1)/($H43-$G43+1)))) -> 0 | M43: =IF($G43=0,0,IF(M$6<$G43,0,IF(M$6>$H43,1,(M$6-$G43+1)/($H43-$G43+1)))) -> 0 | N43: =IF($G43=0,0,IF(N$6<$G43,0,IF(N$6>$H43,1,(N$6-$G43+1)/($H43-$G43+1)))) -> 0 | O43: =IF($G43=0,0,IF(O$6<$G43,0,IF(O$6>$H43,1,(O$6-$G43+1)/($H43-$G43+1)))) -> 0 | P43: =IF($G43=0,0,IF(P$6<$G43,0,IF(P$6>$H43,1,(P$6-$G43+1)/($H43-$G43+1)))) -> 0 | ... BO43: =IF($G43=0,0,IF(BO$6<$G43,0,IF(BO$6>$H43,1,(BO$6-$G43+1)/($H43-$G43+1)))) -> 1
...

Sheet PDT ODS02 Proyectado
B3: CW381147-ODS002: CONSTRUCCIÓN DE PLATAFORMAS Y CIMENTACIONES DE AEROGENERADORES DEL PARQUE EÓLICO WINDPESHI | I3: SEMANAS | K3: 0 | L3: 1 | M3: 2 | N3: 3 | O3: 4 | P3: 5 | Q3: 6 | R3: 7 | S3: 8 | T3: 9 | U3: 10 | V3: 11 | W3: 12 | X3: 13 | Y3: 14 | Z3: 15 | AA3: 16 | AB3: 17 | AC3: 18 | AD3: 19 | AE3: 20 | AF3: 21 | AG3: 22 | AH3: 23 | AI3: 24 | AJ3: 25 | AK3: 26 | AL3: 27 | AM3: 28 | AN3: 29 | AO3: 30 | AP3: 31 | AQ3: 32 | AR3: 33 | AS3: 34 | AT3: 35 | AU3: 36 | AV3: 37 | AW3: 38 | AX3: 39 | AY3: 40 | AZ3: 41 | BA3: 42 | BB3: 43 | BC3: 44 | BD3: 45 | BE3: 46 | BF3: 47 | BG3: 48 | BH3: 49 | BI3: 50 | BJ3: 51 | BK3: 52 | BL3: 53 | BM3: 54 | BN3: 55 | BO3: 56 | BP3: 57 | BQ3: 58
K4: =G8 -> 46218 | L4: =K4+2 -> 46220 | M4: =L4+7 -> 46227 | N4: =M4+7 -> 46234 | O4: =N4+7 -> 46241 | P4: =O4+7 -> 46248 | Q4: =P4+7 -> 46255 | R4: =Q4+7 -> 46262 | S4: =R4+7 -> 46269 | T4: =S4+7 -> 46276 | ... BQ4: =BP4+7 -> 46619
I5: AVANCES PROGRAMADOS | K5: =K7*$E$8 -> 0 | L5: =L7*$E$8 -> 2871440.7 | M5: =M7*$E$8 -> 25521456 | N5: =N7*$E$8 -> 6.4757687e+08 | O5: =O7*$E$8 -> 1.320406e+09 | P5: =P7*$E$8 -> 1.5043962e+09 | Q5: =Q7*$E$8 -> 1.8283878e+09 | R5: =R7*$E$8 -> 2.2925623e+09 | ... BQ5: =BQ7*$E$8 -> 2.0706618e+11
I6: FECHAS | K6: =K4 -> 46218 | L6: =L4 -> 46220 | M6: =M4 -> 46227 | N6: =N4 -> 46234 | O6: =O4 -> 46241 | P6: =P4 -> 46248 | Q6: =Q4 -> 46255 | R6: =R4 -> 46262 | ... BR6: =BR4 -> 0
B7: EDT | C7: Nombre de tarea | D7: Duración | E7: Costo | F7: PESO RELATIVO AL CAPITULO (%) | G7: Comienzo | I7: Fin | K7: =$F34*K34+$F39*K39+$F44*K44+$F109*K109+$F689*K689+$F695*K695+$F699*K699 -> 0 | L7: =$F34*L34+$F39*L39+$F44*L44+$F109*L109+$F689*L689+$F695*L695+$F699*L699 -> 1.3775459e-05 | M7: =$F34*M34+$F39*M39+$F44*M44+$F109*M109+$F689*M689+$F695*M695+$F699*M699 -> 0.00012243672 | N7: =$F34*N34+$F39*N39+$F44*N44+$F109*N109+$F689*N689+$F695*N695+$F699*N699 -> 0.0031066874 | O7: =$F34*O34+$F39*O39+$F44*O44+$F109*O109+$F689*O689+$F695*O695+$F699*O699 -> 0.0063345203 | P7: =$F34*P34+$F39*P39+$F44*P44+$F109*P109+$F689*P689+$F695*P695+$F699*P699 -> 0.0072171954 | Q7: =$F34*Q34+$F39*Q39+$F44*Q44+$F109*Q109+$F689*Q689+$F695*Q695+$F699*Q699 -> 0.0087715138 | R7: =$F34*R34+$F39*R39+$F44*R44+$F109*R109+$F689*R689+$F695*R695+$F699*R699 -> 0.010998346 | ... BQ7: =$F34*BQ34+$F39*BQ39+$F44*BQ44+$F109*BQ109+$F689*BQ689+$F695*BQ695+$F699*BQ699 -> 0.99337996
B8: 0 | C8: ODS02_IIWAKAI | D8: 357 días | E8: =+E34+E39+E44+E109+E689+E695+E699 -> 2.084461e+11 | F8: =+F10+F14++F29+F30+F34+F39+F44+F109+F689+F695+F699 -> 1 | G8: 46218 | I8: 46637 | K8: =K7*$E$8 -> 0 | L8: =L7*$E$8 -> 2871440.7 | M8: =M7*$E$8 -> 25521456 | N8: =N7*$E$8 -> 6.4757687e+08 | O8: =O7*$E$8 -> 1.320406e+09 | P8: =P7*$E$8 -> 1.5043962e+09 | Q8: =Q7*$E$8 -> 1.8283878e+09 | R8: =R7*$E$8 -> 2.2925623e+09 | ... BQ8: =BQ7*$E$8 -> 2.0706618e+11
B9: 1 | C9: HITO 1: ACTA DE INICIO | D9: 0 días | E9: =VLOOKUP(B9,'Cuadro Control'!C5:J1939,8,FALSE) -> 0 | F9: =IFERROR(E9/$E$8,0) -> 0 | G9: 46218 | I9: 46218 | J9: =+INDEX($K9:$BQ9,1,MATCH(I9,$K$6:$BQ$6,1)) -> 1 | K9: =IF($G9=0,0,IF(K$6<$G9,0,IF(K$6>$I9,1,(K$6-$G9+1)/($I9-$G9+1)))) -> 1 | L9: =IF($G9=0,0,IF(L$6<$G9,0,IF(L$6>$I9,1,(L$6-$G9+1)/($I9-$G9+1)))) -> 1 | M9: =IF($G9=0,0,IF(M$6<$G9,0,IF(M$6>$I9,1,(M$6-$G9+1)/($I9-$G9+1)))) -> 1 | N9: =IF($G9=0,0,IF(N$6<$G9,0,IF(N$6>$I9,1,(N$6-$G9+1)/($I9-$G9+1)))) -> 1 | O9: =IF($G9=0,0,IF(O$6<$G9,0,IF(O$6>$I9,1,(O$6-$G9+1)/($I9-$G9+1)))) -> 1 | P9: =IF($G9=0,0,IF(P$6<$G9,0,IF(P$6>$I9,1,(P$6-$G9+1)/($I9-$G9+1)))) -> 1 | Q9: =IF($G9=0,0,IF(Q$6<$G9,0,IF(Q$6>$I9,1,(Q$6-$G9+1)/($I9-$G9+1)))) -> 1 | R9: =IF($G9=0,0,IF(R$6<$G9,0,IF(R$6>$I9,1,(R$6-$G9+1)/($I9-$G9+1)))) -> 1 | ... BQ9: =IF($G9=0,0,IF(BQ$6<$G9,0,IF(BQ$6>$I9,1,(BQ$6-$G9+1)/($I9-$G9+1)))) -> 1 | BR9: =+AVERAGE(K9:BQ9) -> 1
B10: 2 | C10: PRELIMINARES GENERALES | D10: 21 días | E10: =VLOOKUP(B10,'Cuadro Control'!C6:J1940,8,FALSE) -> 0 | F10: =IFERROR(E10/$E$8,0) -> 0 | G10: 46218 | I10: 46268 | J10: =+INDEX($K10:$BQ10,1,MATCH(I10,$K$6:$BQ$6,1)) -> 0.88235294 | K10: =IF($G10=0,0,IF(K$6<$G10,0,IF(K$6>$I10,1,(K$6-$G10+1)/($I10-$G10+1)))) -> 0.019607843 | L10: =IF($G10=0,0,IF(L$6<$G10,0,IF(L$6>$I10,1,(L$6-$G10+1)/($I10-$G10+1)))) -> 0.058823529 | M10: =IF($G10=0,0,IF(M$6<$G10,0,IF(M$6>$I10,1,(M$6-$G10+1)/($I10-$G10+1)))) -> 0.19607843 | N10: =IF($G10=0,0,IF(N$6<$G10,0,IF(N$6>$I10,1,(N$6-$G10+1)/($I10-$G10+1)))) -> 0.33333333 | O10: =IF($G10=0,0,IF(O$6<$G10,0,IF(O$6>$I10,1,(O$6-$G10+1)/($I10-$G10+1)))) -> 0.47058824 | P10: =IF($G10=0,0,IF(P$6<$G10,0,IF(P$6>$I10,1,(P$6-$G10+1)/($I10-$G10+1)))) -> 0.60784314 | Q10: =IF($G10=0,0,IF(Q$6<$G10,0,IF(Q$6>$I10,1,(Q$6-$G10+1)/($I10-$G10+1)))) -> 0.74509804 | R10: =IF($G10=0,0,IF(R$6<$G10,0,IF(R$6>$I10,1,(R$6-$G10+1)/($I10-$G10+1)))) -> 0.88235294 | ... BQ10: =IF($G10=0,0,IF(BQ$6<$G10,0,IF(BQ$6>$I10,1,(BQ$6-$G10+1)/($I10-$G10+1)))) -> 1 | BR10: =+AVERAGE(K10:BQ10) -> 0.92057162
B11: 2.1 | C11: ENTREGA DE DOCUMENTOS HABILITADORES | D11: 0 días | E11: =VLOOKUP(B11,'Cuadro Control'!C7:J1941,8,FALSE) -> 0 | F11: =IFERROR(E11/$E$8,0) -> 0 | G11: 46218 | I11: 46218 | J11: =+INDEX($K11:$BQ11,1,MATCH(I11,$K$6:$BQ$6,1)) -> 1 | K11: =IF($G11=0,0,IF(K$6<$G11,0,IF(K$6>$I11,1,(K$6-$G11+1)/($I11-$G11+1)))) -> 1 | L11: =IF($G11=0,0,IF(L$6<$G11,0,IF(L$6>$I11,1,(L$6-$G11+1)/($I11-$G11+1)))) -> 1 | M11: =IF($G11=0,0,IF(M$6<$G11,0,IF(M$6>$I11,1,(M$6-$G11+1)/($I11-$G11+1)))) -> 1 | N11: =IF($G11=0,0,IF(N$6<$G11,0,IF(N$6>$I11,1,(N$6-$G11+1)/($I11-$G11+1)))) -> 1 | O11: =IF($G11=0,0,IF(O$6<$G11,0,IF(O$6>$I11,1,(O$6-$G11+1)/($I11-$G11+1)))) -> 1 | P11: =IF($G11=0,0,IF(P$6<$G11,0,IF(P$6>$I11,1,(P$6-$G11+1)/($I11-$G11+1)))) -> 1 | Q11: =IF($G11=0,0,IF(Q$6<$G11,0,IF(Q$6>$I11,1,(Q$6-$G11+1)/($I11-$G11+1)))) -> 1 | R11: =IF($G11=0,0,IF(R$6<$G11,0,IF(R$6>$I11,1,(R$6-$G11+1)/($I11-$G11+1)))) -> 1 | ... BQ11: =IF($G11=0,0,IF(BQ$6<$G11,0,IF(BQ$6>$I11,1,(BQ$6-$G11+1)/($I11-$G11+1)))) -> 1 | BR11: =+AVERAGE(K11:BQ11) -> 1
B12: 2.2 | C12: ENTREGA DE DOCUMENTACIÓN DE EJECUCION DEL PROYECTO | D12: 0 días | E12: =VLOOKUP(B12,'Cuadro Control'!C8:J1942,8,FALSE) -> 0 | F12: =IFERROR(E12/$E$8,0) -> 0 | G12: 46218 | I12: 46218 | J12: =+INDEX($K12:$BQ12,1,MATCH(I12,$K$6:$BQ$6,1)) -> 1 | K12: =IF($G12=0,0,IF(K$6<$G12,0,IF(K$6>$I12,1,(K$6-$G12+1)/($I12-$G12+1)))) -> 1 | L12: =IF($G12=0,0,IF(L$6<$G12,0,IF(L$6>$I12,1,(L$6-$G12+1)/($I12-$G12+1)))) -> 1 | M12: =IF($G12=0,0,IF(M$6<$G12,0,IF(M$6>$I12,1,(M$6-$G12+1)/($I12-$G12+1)))) -> 1 | N12: =IF($G12=0,0,IF(N$6<$G12,0,IF(N$6>$I12,1,(N$6-$G12+1)/($I12-$G12+1)))) -> 1 | O12: =IF($G12=0,0,IF(O$6<$G12,0,IF(O$6>$I12,1,(O$6-$G12+1)/($I12-$G12+1)))) -> 1 | P12: =IF($G12=0,0,IF(P$6<$G12,0,IF(P$6>$I12,1,(P$6-$G12+1)/($I12-$G12+1)))) -> 1 | Q12: =IF($G12=0,0,IF(Q$6<$G12,0,IF(Q$6>$I12,1,(Q$6-$G12+1)/($I12-$G12+1)))) -> 1 | R12: =IF($G12=0,0,IF(R$6<$G12,0,IF(R$6>$I12,1,(R$6-$G12+1)/($I12-$G12+1)))) -> 1 | ... BQ12: =IF($G12=0,0,IF(BQ$6<$G12,0,IF(BQ$6>$I12,1,(BQ$6-$G12+1)/($I12-$G12+1)))) -> 1 | BR12: =+AVERAGE(K12:BQ12) -> 1
B13: 2.3 | C13: REVISIÓN Y RECEPCIÓN DE INGENIERIA | D13: 21 días | E13: =VLOOKUP(B13,'Cuadro Control'!C9:J1943,8,FALSE) -> 0 | F13: =IFERROR(E13/$E$8,0) -> 0 | G13: 46218 | I13: 46268 | J13: =+INDEX($K13:$BQ13,1,MATCH(I13,$K$6:$BQ$6,1)) -> 0.88235294 | K13: =IF($G13=0,0,IF(K$6<$G13,0,IF(K$6>$I13,1,(K$6-$G13+1)/($I13-$G13+1)))) -> 0.019607843 | L13: =IF($G13=0,0,IF(L$6<$G13,0,IF(L$6>$I13,1,(L$6-$G13+1)/($I13-$G13+1)))) -> 0.058823529 | M13: =IF($G13=0,0,IF(M$6<$G13,0,IF(M$6>$I13,1,(M$6-$G13+1)/($I13-$G13+1)))) -> 0.19607843 | N13: =IF($G13=0,0,IF(N$6<$G13,0,IF(N$6>$I13,1,(N$6-$G13+1)/($I13-$G13+1)))) -> 0.33333333 | O13: =IF($G13=0,0,IF(O$6<$G13,0,IF(O$6>$I13,1,(O$6-$G13+1)/($I13-$G13+1)))) -> 0.47058824 | P13: =IF($G13=0,0,IF(P$6<$G13,0,IF(P$6>$I13,1,(P$6-$G13+1)/($I13-$G13+1)))) -> 0.60784314 | Q13: =IF($G13=0,0,IF(Q$6<$G13,0,IF(Q$6>$I13,1,(Q$6-$G13+1)/($I13-$G13+1)))) -> 0.74509804 | R13: =IF($G13=0,0,IF(R$6<$G13,0,IF(R$6>$I13,1,(R$6-$G13+1)/($I13-$G13+1)))) -> 0.88235294 | ... BQ13: =IF($G13=0,0,IF(BQ$6<$G13,0,IF(BQ$6>$I13,1,(BQ$6-$G13+1)/($I13-$G13+1)))) -> 1 | BR13: =+AVERAGE(K13:BQ13) -> 0.92057162
